Workbook

Sheet Summary
A2: Group | B2: Team | C2: Shortcut | D2: Badge | P2: Squad
A3: A | B3: Mexico | C3: MEX | D3: =$C3&" "&COLUMNS($D3:D3) -> MEX 1 | E3: =$C3&" "&COLUMNS($D3:E3) -> MEX 2 | F3: =$C3&" "&COLUMNS($D3:F3) -> MEX 3 | G3: =$C3&" "&COLUMNS($D3:G3) -> MEX 4 | H3: =$C3&" "&COLUMNS($D3:H3) -> MEX 5 | I3: =$C3&" "&COLUMNS($D3:I3) -> MEX 6 | J3: =$C3&" "&COLUMNS($D3:J3) -> MEX 7 | K3: =$C3&" "&COLUMNS($D3:K3) -> MEX 8 | ... W3: =$C3&" "&COLUMNS($D3:W3) -> MEX 20
B4: South Africa | C4: RSA | D4: =$C4&" "&COLUMNS($D4:D4) -> RSA 1 | E4: =$C4&" "&COLUMNS($D4:E4) -> RSA 2 | F4: =$C4&" "&COLUMNS($D4:F4) -> RSA 3 | G4: =$C4&" "&COLUMNS($D4:G4) -> RSA 4 | H4: =$C4&" "&COLUMNS($D4:H4) -> RSA 5 | I4: =$C4&" "&COLUMNS($D4:I4) -> RSA 6 | J4: =$C4&" "&COLUMNS($D4:J4) -> RSA 7 | K4: =$C4&" "&COLUMNS($D4:K4) -> RSA 8 | ... W4: =$C4&" "&COLUMNS($D4:W4) -> RSA 20
B5: Korea Republic | C5: KOR | D5: =$C5&" "&COLUMNS($D5:D5) -> KOR 1 | E5: =$C5&" "&COLUMNS($D5:E5) -> KOR 2 | F5: =$C5&" "&COLUMNS($D5:F5) -> KOR 3 | G5: =$C5&" "&COLUMNS($D5:G5) -> KOR 4 | H5: =$C5&" "&COLUMNS($D5:H5) -> KOR 5 | I5: =$C5&" "&COLUMNS($D5:I5) -> KOR 6 | J5: =$C5&" "&COLUMNS($D5:J5) -> KOR 7 | K5: =$C5&" "&COLUMNS($D5:K5) -> KOR 8 | ... W5: =$C5&" "&COLUMNS($D5:W5) -> KOR 20
B6: Czechia | C6: CZE | D6: =$C6&" "&COLUMNS($D6:D6) -> CZE 1 | E6: =$C6&" "&COLUMNS($D6:E6) -> CZE 2 | F6: =$C6&" "&COLUMNS($D6:F6) -> CZE 3 | G6: =$C6&" "&COLUMNS($D6:G6) -> CZE 4 | H6: =$C6&" "&COLUMNS($D6:H6) -> CZE 5 | I6: =$C6&" "&COLUMNS($D6:I6) -> CZE 6 | J6: =$C6&" "&COLUMNS($D6:J6) -> CZE 7 | K6: =$C6&" "&COLUMNS($D6:K6) -> CZE 8 | ... W6: =$C6&" "&COLUMNS($D6:W6) -> CZE 20
A8: B | B8: Canada | C8: CAN | D8: =$C8&" "&COLUMNS($D8:D8) -> CAN 1 | E8: =$C8&" "&COLUMNS($D8:E8) -> CAN 2 | F8: =$C8&" "&COLUMNS($D8:F8) -> CAN 3 | G8: =$C8&" "&COLUMNS($D8:G8) -> CAN 4 | H8: =$C8&" "&COLUMNS($D8:H8) -> CAN 5 | I8: =$C8&" "&COLUMNS($D8:I8) -> CAN 6 | J8: =$C8&" "&COLUMNS($D8:J8) -> CAN 7 | K8: =$C8&" "&COLUMNS($D8:K8) -> CAN 8 | ... W8: =$C8&" "&COLUMNS($D8:W8) -> CAN 20
B9: Bosnia-Herzegovina | C9: BIH | D9: =$C9&" "&COLUMNS($D9:D9) -> BIH 1 | E9: =$C9&" "&COLUMNS($D9:E9) -> BIH 2 | F9: =$C9&" "&COLUMNS($D9:F9) -> BIH 3 | G9: =$C9&" "&COLUMNS($D9:G9) -> BIH 4 | H9: =$C9&" "&COLUMNS($D9:H9) -> BIH 5 | I9: =$C9&" "&COLUMNS($D9:I9) -> BIH 6 | J9: =$C9&" "&COLUMNS($D9:J9) -> BIH 7 | K9: =$C9&" "&COLUMNS($D9:K9) -> BIH 8 | ... W9: =$C9&" "&COLUMNS($D9:W9) -> BIH 20
B10: Qatar | C10: QAT | D10: =$C10&" "&COLUMNS($D10:D10) -> QAT 1 | E10: =$C10&" "&COLUMNS($D10:E10) -> QAT 2 | F10: =$C10&" "&COLUMNS($D10:F10) -> QAT 3 | G10: =$C10&" "&COLUMNS($D10:G10) -> QAT 4 | H10: =$C10&" "&COLUMNS($D10:H10) -> QAT 5 | I10: =$C10&" "&COLUMNS($D10:I10) -> QAT 6 | J10: =$C10&" "&COLUMNS($D10:J10) -> QAT 7 | K10: =$C10&" "&COLUMNS($D10:K10) -> QAT 8 | ... W10: =$C10&" "&COLUMNS($D10:W10) -> QAT 20
B11: Switzerland | C11: SUI | D11: =$C11&" "&COLUMNS($D11:D11) -> SUI 1 | E11: =$C11&" "&COLUMNS($D11:E11) -> SUI 2 | F11: =$C11&" "&COLUMNS($D11:F11) -> SUI 3 | G11: =$C11&" "&COLUMNS($D11:G11) -> SUI 4 | H11: =$C11&" "&COLUMNS($D11:H11) -> SUI 5 | I11: =$C11&" "&COLUMNS($D11:I11) -> SUI 6 | J11: =$C11&" "&COLUMNS($D11:J11) -> SUI 7 | K11: =$C11&" "&COLUMNS($D11:K11) -> SUI 8 | ... W11: =$C11&" "&COLUMNS($D11:W11) -> SUI 20
A13: C | B13: Brazil | C13: BRA | D13: =$C13&" "&COLUMNS($D13:D13) -> BRA 1 | E13: =$C13&" "&COLUMNS($D13:E13) -> BRA 2 | F13: =$C13&" "&COLUMNS($D13:F13) -> BRA 3 | G13: =$C13&" "&COLUMNS($D13:G13) -> BRA 4 | H13: =$C13&" "&COLUMNS($D13:H13) -> BRA 5 | I13: =$C13&" "&COLUMNS($D13:I13) -> BRA 6 | J13: =$C13&" "&COLUMNS($D13:J13) -> BRA 7 | K13: =$C13&" "&COLUMNS($D13:K13) -> BRA 8 | ... W13: =$C13&" "&COLUMNS($D13:W13) -> BRA 20
B14: Morocco | C14: MAR | D14: =$C14&" "&COLUMNS($D14:D14) -> MAR 1 | E14: =$C14&" "&COLUMNS($D14:E14) -> MAR 2 | F14: =$C14&" "&COLUMNS($D14:F14) -> MAR 3 | G14: =$C14&" "&COLUMNS($D14:G14) -> MAR 4 | H14: =$C14&" "&COLUMNS($D14:H14) -> MAR 5 | I14: =$C14&" "&COLUMNS($D14:I14) -> MAR 6 | J14: =$C14&" "&COLUMNS($D14:J14) -> MAR 7 | K14: =$C14&" "&COLUMNS($D14:K14) -> MAR 8 | ... W14: =$C14&" "&COLUMNS($D14:W14) -> MAR 20
B15: Haiti | C15: HAI | D15: =$C15&" "&COLUMNS($D15:D15) -> HAI 1 | E15: =$C15&" "&COLUMNS($D15:E15) -> HAI 2 | F15: =$C15&" "&COLUMNS($D15:F15) -> HAI 3 | G15: =$C15&" "&COLUMNS($D15:G15) -> HAI 4 | H15: =$C15&" "&COLUMNS($D15:H15) -> HAI 5 | I15: =$C15&" "&COLUMNS($D15:I15) -> HAI 6 | J15: =$C15&" "&COLUMNS($D15:J15) -> HAI 7 | K15: =$C15&" "&COLUMNS($D15:K15) -> HAI 8 | ... W15: =$C15&" "&COLUMNS($D15:W15) -> HAI 20
B16: Scotland | C16: SCO | D16: =$C16&" "&COLUMNS($D16:D16) -> SCO 1 | E16: =$C16&" "&COLUMNS($D16:E16) -> SCO 2 | F16: =$C16&" "&COLUMNS($D16:F16) -> SCO 3 | G16: =$C16&" "&COLUMNS($D16:G16) -> SCO 4 | H16: =$C16&" "&COLUMNS($D16:H16) -> SCO 5 | I16: =$C16&" "&COLUMNS($D16:I16) -> SCO 6 | J16: =$C16&" "&COLUMNS($D16:J16) -> SCO 7 | K16: =$C16&" "&COLUMNS($D16:K16) -> SCO 8 | ... W16: =$C16&" "&COLUMNS($D16:W16) -> SCO 20
A18: D | B18: USA | C18: USA | D18: =$C18&" "&COLUMNS($D18:D18) -> USA 1 | E18: =$C18&" "&COLUMNS($D18:E18) -> USA 2 | F18: =$C18&" "&COLUMNS($D18:F18) -> USA 3 | G18: =$C18&" "&COLUMNS($D18:G18) -> USA 4 | H18: =$C18&" "&COLUMNS($D18:H18) -> USA 5 | I18: =$C18&" "&COLUMNS($D18:I18) -> USA 6 | J18: =$C18&" "&COLUMNS($D18:J18) -> USA 7 | K18: =$C18&" "&COLUMNS($D18:K18) -> USA 8 | ... W18: =$C18&" "&COLUMNS($D18:W18) -> USA 20
B19: Paraguay | C19: PAR | D19: =$C19&" "&COLUMNS($D19:D19) -> PAR 1 | E19: =$C19&" "&COLUMNS($D19:E19) -> PAR 2 | F19: =$C19&" "&COLUMNS($D19:F19) -> PAR 3 | G19: =$C19&" "&COLUMNS($D19:G19) -> PAR 4 | H19: =$C19&" "&COLUMNS($D19:H19) -> PAR 5 | I19: =$C19&" "&COLUMNS($D19:I19) -> PAR 6 | J19: =$C19&" "&COLUMNS($D19:J19) -> PAR 7 | K19: =$C19&" "&COLUMNS($D19:K19) -> PAR 8 | ... W19: =$C19&" "&COLUMNS($D19:W19) -> PAR 20
B20: Australia | C20: AUS | D20: =$C20&" "&COLUMNS($D20:D20) -> AUS 1 | E20: =$C20&" "&COLUMNS($D20:E20) -> AUS 2 | F20: =$C20&" "&COLUMNS($D20:F20) -> AUS 3 | G20: =$C20&" "&COLUMNS($D20:G20) -> AUS 4 | H20: =$C20&" "&COLUMNS($D20:H20) -> AUS 5 | I20: =$C20&" "&COLUMNS($D20:I20) -> AUS 6 | J20: =$C20&" "&COLUMNS($D20:J20) -> AUS 7 | K20: =$C20&" "&COLUMNS($D20:K20) -> AUS 8 | ... W20: =$C20&" "&COLUMNS($D20:W20) -> AUS 20
B21: Türkiye | C21: TUR | D21: =$C21&" "&COLUMNS($D21:D21) -> TUR 1 | E21: =$C21&" "&COLUMNS($D21:E21) -> TUR 2 | F21: =$C21&" "&COLUMNS($D21:F21) -> TUR 3 | G21: =$C21&" "&COLUMNS($D21:G21) -> TUR 4 | H21: =$C21&" "&COLUMNS($D21:H21) -> TUR 5 | I21: =$C21&" "&COLUMNS($D21:I21) -> TUR 6 | J21: =$C21&" "&COLUMNS($D21:J21) -> TUR 7 | K21: =$C21&" "&COLUMNS($D21:K21) -> TUR 8 | ... W21: =$C21&" "&COLUMNS($D21:W21) -> TUR 20
A23: E | B23: Germany | C23: GER | D23: =$C23&" "&COLUMNS($D23:D23) -> GER 1 | E23: =$C23&" "&COLUMNS($D23:E23) -> GER 2 | F23: =$C23&" "&COLUMNS($D23:F23) -> GER 3 | G23: =$C23&" "&COLUMNS($D23:G23) -> GER 4 | H23: =$C23&" "&COLUMNS($D23:H23) -> GER 5 | I23: =$C23&" "&COLUMNS($D23:I23) -> GER 6 | J23: =$C23&" "&COLUMNS($D23:J23) -> GER 7 | K23: =$C23&" "&COLUMNS($D23:K23) -> GER 8 | ... W23: =$C23&" "&COLUMNS($D23:W23) -> GER 20
B24: Curaçao | C24: CUW | D24: =$C24&" "&COLUMNS($D24:D24) -> CUW 1 | E24: =$C24&" "&COLUMNS($D24:E24) -> CUW 2 | F24: =$C24&" "&COLUMNS($D24:F24) -> CUW 3 | G24: =$C24&" "&COLUMNS($D24:G24) -> CUW 4 | H24: =$C24&" "&COLUMNS($D24:H24) -> CUW 5 | I24: =$C24&" "&COLUMNS($D24:I24) -> CUW 6 | J24: =$C24&" "&COLUMNS($D24:J24) -> CUW 7 | K24: =$C24&" "&COLUMNS($D24:K24) -> CUW 8 | ... W24: =$C24&" "&COLUMNS($D24:W24) -> CUW 20
B25: Côte d’Ivoire | C25: CIV | D25: =$C25&" "&COLUMNS($D25:D25) -> CIV 1 | E25: =$C25&" "&COLUMNS($D25:E25) -> CIV 2 | F25: =$C25&" "&COLUMNS($D25:F25) -> CIV 3 | G25: =$C25&" "&COLUMNS($D25:G25) -> CIV 4 | H25: =$C25&" "&COLUMNS($D25:H25) -> CIV 5 | I25: =$C25&" "&COLUMNS($D25:I25) -> CIV 6 | J25: =$C25&" "&COLUMNS($D25:J25) -> CIV 7 | K25: =$C25&" "&COLUMNS($D25:K25) -> CIV 8 | ... W25: =$C25&" "&COLUMNS($D25:W25) -> CIV 20
B26: Ecuador | C26: ECU | D26: =$C26&" "&COLUMNS($D26:D26) -> ECU 1 | E26: =$C26&" "&COLUMNS($D26:E26) -> ECU 2 | F26: =$C26&" "&COLUMNS($D26:F26) -> ECU 3 | G26: =$C26&" "&COLUMNS($D26:G26) -> ECU 4 | H26: =$C26&" "&COLUMNS($D26:H26) -> ECU 5 | I26: =$C26&" "&COLUMNS($D26:I26) -> ECU 6 | J26: =$C26&" "&COLUMNS($D26:J26) -> ECU 7 | K26: =$C26&" "&COLUMNS($D26:K26) -> ECU 8 | ... W26: =$C26&" "&COLUMNS($D26:W26) -> ECU 20
A28: F | B28: Netherlands | C28: NED | D28: =$C28&" "&COLUMNS($D28:D28) -> NED 1 | E28: =$C28&" "&COLUMNS($D28:E28) -> NED 2 | F28: =$C28&" "&COLUMNS($D28:F28) -> NED 3 | G28: =$C28&" "&COLUMNS($D28:G28) -> NED 4 | H28: =$C28&" "&COLUMNS($D28:H28) -> NED 5 | I28: =$C28&" "&COLUMNS($D28:I28) -> NED 6 | J28: =$C28&" "&COLUMNS($D28:J28) -> NED 7 | K28: =$C28&" "&COLUMNS($D28:K28) -> NED 8 | ... W28: =$C28&" "&COLUMNS($D28:W28) -> NED 20
B29: Japan | C29: JPN | D29: =$C29&" "&COLUMNS($D29:D29) -> JPN 1 | E29: =$C29&" "&COLUMNS($D29:E29) -> JPN 2 | F29: =$C29&" "&COLUMNS($D29:F29) -> JPN 3 | G29: =$C29&" "&COLUMNS($D29:G29) -> JPN 4 | H29: =$C29&" "&COLUMNS($D29:H29) -> JPN 5 | I29: =$C29&" "&COLUMNS($D29:I29) -> JPN 6 | J29: =$C29&" "&COLUMNS($D29:J29) -> JPN 7 | K29: =$C29&" "&COLUMNS($D29:K29) -> JPN 8 | ... W29: =$C29&" "&COLUMNS($D29:W29) -> JPN 20
B30: Sweden | C30: SWE | D30: =$C30&" "&COLUMNS($D30:D30) -> SWE 1 | E30: =$C30&" "&COLUMNS($D30:E30) -> SWE 2 | F30: =$C30&" "&COLUMNS($D30:F30) -> SWE 3 | G30: =$C30&" "&COLUMNS($D30:G30) -> SWE 4 | H30: =$C30&" "&COLUMNS($D30:H30) -> SWE 5 | I30: =$C30&" "&COLUMNS($D30:I30) -> SWE 6 | J30: =$C30&" "&COLUMNS($D30:J30) -> SWE 7 | K30: =$C30&" "&COLUMNS($D30:K30) -> SWE 8 | ... W30: =$C30&" "&COLUMNS($D30:W30) -> SWE 20
B31: Tunisia | C31: TUN | D31: =$C31&" "&COLUMNS($D31:D31) -> TUN 1 | E31: =$C31&" "&COLUMNS($D31:E31) -> TUN 2 | F31: =$C31&" "&COLUMNS($D31:F31) -> TUN 3 | G31: =$C31&" "&COLUMNS($D31:G31) -> TUN 4 | H31: =$C31&" "&COLUMNS($D31:H31) -> TUN 5 | I31: =$C31&" "&COLUMNS($D31:I31) -> TUN 6 | J31: =$C31&" "&COLUMNS($D31:J31) -> TUN 7 | K31: =$C31&" "&COLUMNS($D31:K31) -> TUN 8 | ... W31: =$C31&" "&COLUMNS($D31:W31) -> TUN 20
A33: G | B33: Belgium | C33: BEL | D33: =$C33&" "&COLUMNS($D33:D33) -> BEL 1 | E33: =$C33&" "&COLUMNS($D33:E33) -> BEL 2 | F33: =$C33&" "&COLUMNS($D33:F33) -> BEL 3 | G33: =$C33&" "&COLUMNS($D33:G33) -> BEL 4 | H33: =$C33&" "&COLUMNS($D33:H33) -> BEL 5 | I33: =$C33&" "&COLUMNS($D33:I33) -> BEL 6 | J33: =$C33&" "&COLUMNS($D33:J33) -> BEL 7 | K33: =$C33&" "&COLUMNS($D33:K33) -> BEL 8 | ... W33: =$C33&" "&COLUMNS($D33:W33) -> BEL 20
B34: Egypt | C34: EGY | D34: =$C34&" "&COLUMNS($D34:D34) -> EGY 1 | E34: =$C34&" "&COLUMNS($D34:E34) -> EGY 2 | F34: =$C34&" "&COLUMNS($D34:F34) -> EGY 3 | G34: =$C34&" "&COLUMNS($D34:G34) -> EGY 4 | H34: =$C34&" "&COLUMNS($D34:H34) -> EGY 5 | I34: =$C34&" "&COLUMNS($D34:I34) -> EGY 6 | J34: =$C34&" "&COLUMNS($D34:J34) -> EGY 7 | K34: =$C34&" "&COLUMNS($D34:K34) -> EGY 8 | ... W34: =$C34&" "&COLUMNS($D34:W34) -> EGY 20
B35: IR Iran | C35: IRN | D35: =$C35&" "&COLUMNS($D35:D35) -> IRN 1 | E35: =$C35&" "&COLUMNS($D35:E35) -> IRN 2 | F35: =$C35&" "&COLUMNS($D35:F35) -> IRN 3 | G35: =$C35&" "&COLUMNS($D35:G35) -> IRN 4 | H35: =$C35&" "&COLUMNS($D35:H35) -> IRN 5 | I35: =$C35&" "&COLUMNS($D35:I35) -> IRN 6 | J35: =$C35&" "&COLUMNS($D35:J35) -> IRN 7 | K35: =$C35&" "&COLUMNS($D35:K35) -> IRN 8 | ... W35: =$C35&" "&COLUMNS($D35:W35) -> IRN 20
B36: New Zealand | C36: NZL | D36: =$C36&" "&COLUMNS($D36:D36) -> NZL 1 | E36: =$C36&" "&COLUMNS($D36:E36) -> NZL 2 | F36: =$C36&" "&COLUMNS($D36:F36) -> NZL 3 | G36: =$C36&" "&COLUMNS($D36:G36) -> NZL 4 | H36: =$C36&" "&COLUMNS($D36:H36) -> NZL 5 | I36: =$C36&" "&COLUMNS($D36:I36) -> NZL 6 | J36: =$C36&" "&COLUMNS($D36:J36) -> NZL 7 | K36: =$C36&" "&COLUMNS($D36:K36) -> NZL 8 | ... W36: =$C36&" "&COLUMNS($D36:W36) -> NZL 20
A38: H | B38: Spain | C38: ESP | D38: =$C38&" "&COLUMNS($D38:D38) -> ESP 1 | E38: =$C38&" "&COLUMNS($D38:E38) -> ESP 2 | F38: =$C38&" "&COLUMNS($D38:F38) -> ESP 3 | G38: =$C38&" "&COLUMNS($D38:G38) -> ESP 4 | H38: =$C38&" "&COLUMNS($D38:H38) -> ESP 5 | I38: =$C38&" "&COLUMNS($D38:I38) -> ESP 6 | J38: =$C38&" "&COLUMNS($D38:J38) -> ESP 7 | K38: =$C38&" "&COLUMNS($D38:K38) -> ESP 8 | ... W38: =$C38&" "&COLUMNS($D38:W38) -> ESP 20
B39: Cabo Verde | C39: CPV | D39: =$C39&" "&COLUMNS($D39:D39) -> CPV 1 | E39: =$C39&" "&COLUMNS($D39:E39) -> CPV 2 | F39: =$C39&" "&COLUMNS($D39:F39) -> CPV 3 | G39: =$C39&" "&COLUMNS($D39:G39) -> CPV 4 | H39: =$C39&" "&COLUMNS($D39:H39) -> CPV 5 | I39: =$C39&" "&COLUMNS($D39:I39) -> CPV 6 | J39: =$C39&" "&COLUMNS($D39:J39) -> CPV 7 | K39: =$C39&" "&COLUMNS($D39:K39) -> CPV 8 | ... W39: =$C39&" "&COLUMNS($D39:W39) -> CPV 20
B40: Saudi Arabia | C40: KSA | D40: =$C40&" "&COLUMNS($D40:D40) -> KSA 1 | E40: =$C40&" "&COLUMNS($D40:E40) -> KSA 2 | F40: =$C40&" "&COLUMNS($D40:F40) -> KSA 3 | G40: =$C40&" "&COLUMNS($D40:G40) -> KSA 4 | H40: =$C40&" "&COLUMNS($D40:H40) -> KSA 5 | I40: =$C40&" "&COLUMNS($D40:I40) -> KSA 6 | J40: =$C40&" "&COLUMNS($D40:J40) -> KSA 7 | K40: =$C40&" "&COLUMNS($D40:K40) -> KSA 8 | ... W40: =$C40&" "&COLUMNS($D40:W40) -> KSA 20
B41: Uruguay | C41: URU | D41: =$C41&" "&COLUMNS($D41:D41) -> URU 1 | E41: =$C41&" "&COLUMNS($D41:E41) -> URU 2 | F41: =$C41&" "&COLUMNS($D41:F41) -> URU 3 | G41: =$C41&" "&COLUMNS($D41:G41) -> URU 4 | H41: =$C41&" "&COLUMNS($D41:H41) -> URU 5 | I41: =$C41&" "&COLUMNS($D41:I41) -> URU 6 | J41: =$C41&" "&COLUMNS($D41:J41) -> URU 7 | K41: =$C41&" "&COLUMNS($D41:K41) -> URU 8 | ... W41: =$C41&" "&COLUMNS($D41:W41) -> URU 20
A43: I | B43: France | C43: FRA | D43: =$C43&" "&COLUMNS($D43:D43) -> FRA 1 | E43: =$C43&" "&COLUMNS($D43:E43) -> FRA 2 | F43: =$C43&" "&COLUMNS($D43:F43) -> FRA 3 | G43: =$C43&" "&COLUMNS($D43:G43) -> FRA 4 | H43: =$C43&" "&COLUMNS($D43:H43) -> FRA 5 | I43: =$C43&" "&COLUMNS($D43:I43) -> FRA 6 | J43: =$C43&" "&COLUMNS($D43:J43) -> FRA 7 | K43: =$C43&" "&COLUMNS($D43:K43) -> FRA 8 | ... W43: =$C43&" "&COLUMNS($D43:W43) -> FRA 20
B44: Senegal | C44: SEN | D44: =$C44&" "&COLUMNS($D44:D44) -> SEN 1 | E44: =$C44&" "&COLUMNS($D44:E44) -> SEN 2 | F44: =$C44&" "&COLUMNS($D44:F44) -> SEN 3 | G44: =$C44&" "&COLUMNS($D44:G44) -> SEN 4 | H44: =$C44&" "&COLUMNS($D44:H44) -> SEN 5 | I44: =$C44&" "&COLUMNS($D44:I44) -> SEN 6 | J44: =$C44&" "&COLUMNS($D44:J44) -> SEN 7 | K44: =$C44&" "&COLUMNS($D44:K44) -> SEN 8 | ... W44: =$C44&" "&COLUMNS($D44:W44) -> SEN 20
B45: Iraq | C45: IRQ | D45: =$C45&" "&COLUMNS($D45:D45) -> IRQ 1 | E45: =$C45&" "&COLUMNS($D45:E45) -> IRQ 2 | F45: =$C45&" "&COLUMNS($D45:F45) -> IRQ 3 | G45: =$C45&" "&COLUMNS($D45:G45) -> IRQ 4 | H45: =$C45&" "&COLUMNS($D45:H45) -> IRQ 5 | I45: =$C45&" "&COLUMNS($D45:I45) -> IRQ 6 | J45: =$C45&" "&COLUMNS($D45:J45) -> IRQ 7 | K45: =$C45&" "&COLUMNS($D45:K45) -> IRQ 8 | ... W45: =$C45&" "&COLUMNS($D45:W45) -> IRQ 20
B46: Norway | C46: NOR | D46: =$C46&" "&COLUMNS($D46:D46) -> NOR 1 | E46: =$C46&" "&COLUMNS($D46:E46) -> NOR 2 | F46: =$C46&" "&COLUMNS($D46:F46) -> NOR 3 | G46: =$C46&" "&COLUMNS($D46:G46) -> NOR 4 | H46: =$C46&" "&COLUMNS($D46:H46) -> NOR 5 | I46: =$C46&" "&COLUMNS($D46:I46) -> NOR 6 | J46: =$C46&" "&COLUMNS($D46:J46) -> NOR 7 | K46: =$C46&" "&COLUMNS($D46:K46) -> NOR 8 | ... W46: =$C46&" "&COLUMNS($D46:W46) -> NOR 20
A48: J | B48: Argentina | C48: ARG | D48: =$C48&" "&COLUMNS($D48:D48) -> ARG 1 | E48: =$C48&" "&COLUMNS($D48:E48) -> ARG 2 | F48: =$C48&" "&COLUMNS($D48:F48) -> ARG 3 | G48: =$C48&" "&COLUMNS($D48:G48) -> ARG 4 | H48: =$C48&" "&COLUMNS($D48:H48) -> ARG 5 | I48: =$C48&" "&COLUMNS($D48:I48) -> ARG 6 | J48: =$C48&" "&COLUMNS($D48:J48) -> ARG 7 | K48: =$C48&" "&COLUMNS($D48:K48) -> ARG 8 | ... W48: =$C48&" "&COLUMNS($D48:W48) -> ARG 20
B49: Algeria | C49: ALG | D49: =$C49&" "&COLUMNS($D49:D49) -> ALG 1 | E49: =$C49&" "&COLUMNS($D49:E49) -> ALG 2 | F49: =$C49&" "&COLUMNS($D49:F49) -> ALG 3 | G49: =$C49&" "&COLUMNS($D49:G49) -> ALG 4 | H49: =$C49&" "&COLUMNS($D49:H49) -> ALG 5 | I49: =$C49&" "&COLUMNS($D49:I49) -> ALG 6 | J49: =$C49&" "&COLUMNS($D49:J49) -> ALG 7 | K49: =$C49&" "&COLUMNS($D49:K49) -> ALG 8 | ... W49: =$C49&" "&COLUMNS($D49:W49) -> ALG 20
B50: Austria | C50: AUT | D50: =$C50&" "&COLUMNS($D50:D50) -> AUT 1 | E50: =$C50&" "&COLUMNS($D50:E50) -> AUT 2 | F50: =$C50&" "&COLUMNS($D50:F50) -> AUT 3 | G50: =$C50&" "&COLUMNS($D50:G50) -> AUT 4 | H50: =$C50&" "&COLUMNS($D50:H50) -> AUT 5 | I50: =$C50&" "&COLUMNS($D50:I50) -> AUT 6 | J50: =$C50&" "&COLUMNS($D50:J50) -> AUT 7 | K50: =$C50&" "&COLUMNS($D50:K50) -> AUT 8 | ... W50: =$C50&" "&COLUMNS($D50:W50) -> AUT 20
...

Sheet A-B
A2: A | B2: A
B3: Mexico | E3: South Africa | H3: Korea Republic | K3: Czechia
B4: MEX | E4: RSA | H4: KOR | K4: CZE
A5: 1 | B5: Badge | C5: 0 | D5: 1 | E5: Badge | F5: 0 | G5: 1 | H5: Badge | I5: 0 | J5: 1 | K5: Badge | L5: 0
A6: 2 | B6: Luis Malagón | C6: 0 | D6: 2 | E6: Ronwen Williams | F6: 0 | G6: 2 | H6: Hyeon-woo Jo | I6: 0 | J6: 2 | K6: Matěj Kovář | L6: 0
A7: 3 | B7: Johan Vásquez | C7: 0 | D7: 3 | E7: Sipho Chaine | F7: 0 | G7: 3 | H7: Seung-gyu Kim | I7: 0 | J7: 3 | K7: Jindřich Staněk | L7: 0
A8: 4 | B8: Jorge Sánchez | C8: 0 | D8: 4 | E8: Aubrey Modiba | F8: 0 | G8: 4 | H8: Min-jae Kim | I8: 0 | J8: 4 | K8: Ladislav Krejčí | L8: 0
A9: 5 | B9: César Montes | C9: 0 | D9: 5 | E9: Samukele Kabini | F9: 0 | G9: 5 | H9: Yu-min Cho | I9: 0 | J9: 5 | K9: Vladimír Coufal | L9: 0
A10: 6 | B10: Jesús Gallardo | C10: 0 | D10: 6 | E10: Mbekezeli Mbokazi | F10: 0 | G10: 6 | H10: Young-woo Seol | I10: 0 | J10: 6 | K10: Jaroslav Zelený | L10: 0
A11: 7 | B11: Israel Reyes | C11: 0 | D11: 7 | E11: Khulumani Ndamane | F11: 0 | G11: 7 | H11: Han-beom Lee | I11: 0 | J11: 7 | K11: Tomáš Holeš | L11: 0
A12: 8 | B12: Diego Lainez | C12: 0 | D12: 8 | E12: Siyabonga Ngezana | F12: 0 | G12: 8 | H12: Tae-seok Lee | I12: 0 | J12: 8 | K12: David Zima | L12: 0
A13: 9 | B13: Carlos Rodríguez | C13: 0 | D13: 9 | E13: Khuliso Mudau | F13: 0 | G13: 9 | H13: Myung-jae Lee | I13: 0 | J13: 9 | K13: Michal Sadílek | L13: 0
A14: 10 | B14: Edson Álvarez | C14: 0 | D14: 10 | E14: Nkosinathi Sibisi | F14: 0 | G14: 10 | H14: Jae-sung Lee | I14: 0 | J14: 10 | K14: Lukáš Provod | L14: 0
A15: 11 | B15: Orbelin Pineda | C15: 0 | D15: 11 | E15: Teboho Mokoena | F15: 0 | G15: 11 | H15: In-beom Hwang | I15: 0 | J15: 11 | K15: Lukáš Červ | L15: 0
A16: 12 | B16: Marcel Ruiz | C16: 0 | D16: 12 | E16: Thalente Mbatha | F16: 0 | G16: 12 | H16: Kang-in Lee | I16: 0 | J16: 12 | K16: Tomáš Souček | L16: 0
... A24: 20 | B24: César Huerta | C24: 0 | D24: 20 | E24: Oswin Appollis | F24: 0 | G24: 20 | H24: Hyeon-gyu Oh | I24: 0 | J24: 20 | K24: Patrik Schick | L24: 0
A26: B
B27: Canada | E27: Bosnia & Herzegovina | H27: Qatar | K27: Switzerland
B28: CAN | E28: BIH | H28: QAT | K28: SUI
A29: 1 | B29: Badge | C29: 0 | D29: 1 | E29: Badge | F29: 0 | G29: 1 | H29: Badge | I29: 0 | J29: 1 | K29: Badge | L29: 0
A30: 2 | B30: Dayne St. Clair | C30: 0 | D30: 2 | E30: Nikola Vasilj | F30: 0 | G30: 2 | H30: Meshaal Barsham | I30: 0 | J30: 2 | K30: Gregor Kobel | L30: 0
A31: 3 | B31: Alphonso Davies | C31: 0 | D31: 3 | E31: Amar Dedić | F31: 0 | G31: 3 | H31: Sultan Albrake | I31: 0 | J31: 3 | K31: Yvon Mvogo | L31: 0
A32: 4 | B32: Alistair Johnston | C32: 0 | D32: 4 | E32: Sead Kolašinac | F32: 0 | G32: 4 | H32: Lucas Mendes | I32: 0 | J32: 4 | K32: Manuel Akanji | L32: 0
A33: 5 | B33: Samuel Adekugbe | C33: 0 | D33: 5 | E33: Tarik Muharemović | F33: 0 | G33: 5 | H33: Homam Ahmed | I33: 1 | J33: 5 | K33: Ricardo Rodríguez | L33: 0
A34: 6 | B34: Richie Laryea | C34: 0 | D34: 6 | E34: Nihad Mujakić | F34: 0 | G34: 6 | H34: Boualem Khoukhi | I34: 0 | J34: 6 | K34: Nico Elvedi | L34: 0
A35: 7 | B35: Derek Cornelius | C35: 0 | D35: 7 | E35: Nikola Katić | F35: 0 | G35: 7 | H35: Pedro Miguel | I35: 0 | J35: 7 | K35: Aurèle Amenda | L35: 0
A36: 8 | B36: Moïse Bombito | C36: 0 | D36: 8 | E36: Amir Hadžiahmetović | F36: 0 | G36: 8 | H36: Tarek Salman | I36: 0 | J36: 8 | K36: Silvan Widmer | L36: 0
A37: 9 | B37: Kamal Miller | C37: 0 | D37: 9 | E37: Benjamin Tahirović | F37: 0 | G37: 9 | H37: Mohammed Mannai | I37: 0 | J37: 9 | K37: Granit Xhaka | L37: 0
A38: 10 | B38: Stephen Eustáquio | C38: 0 | D38: 10 | E38: Armin Gigović | F38: 0 | G38: 10 | H38: Karim Boudiaf | I38: 0 | J38: 10 | K38: Denis Zakaria | L38: 0
A39: 11 | B39: Ismaël Koné | C39: 0 | D39: 11 | E39: Ivan Šunjić | F39: 0 | G39: 11 | H39: Assim Madibo | I39: 0 | J39: 11 | K39: Remo Freuler | L39: 0
A40: 12 | B40: Jonathan Osorio | C40: 0 | D40: 12 | E40: Ivan Bašić | F40: 0 | G40: 12 | H40: Hamed Fatehi | I40: 0 | J40: 12 | K40: Fabian Rieder | L40: 0
... A48: 20 | B48: Jonathan David | C48: 0 | D48: 20 | E48: Haris Tabaković | F48: 0 | G48: 20 | H48: Almoez Ali | I48: 0 | J48: 20 | K48: Zeki Amdouni | L48: 0

Sheet C-D
A2: C | B2: C
B3: Brazil | E3: Morocco | H3: Haiti | K3: Scotland
B4: BRA | E4: MAR | H4: HAI | K4: SCO
A5: 1 | B5: Badge | C5: 0 | D5: 1 | E5: Badge | F5: 0 | G5: 1 | H5: Badge | I5: 0 | J5: 1 | K5: Badge | L5: 0
A6: 2 | B6: Alisson | C6: 0 | D6: 2 | E6: Yassine Bounou | F6: 0 | G6: 2 | H6: Johny Placide | I6: 0 | J6: 2 | K6: Angus Gunn | L6: 0
A7: 3 | B7: Bento | C7: 0 | D7: 3 | E7: Munir El Kajoui | F7: 0 | G7: 3 | H7: Carlens Arcus | I7: 0 | J7: 3 | K7: Jack Hendry | L7: 0
A8: 4 | B8: Marquinhos | C8: 0 | D8: 4 | E8: Achraf Hakimi | F8: 0 | G8: 4 | H8: Martin Expérience | I8: 0 | J8: 4 | K8: Kieran Tierney | L8: 0
A9: 5 | B9: Éder Militão | C9: 0 | D9: 5 | E9: Noussair Mazraoui | F9: 0 | G9: 5 | H9: Jean-Kévin Duverne | I9: 0 | J9: 5 | K9: Aaron Hickey | L9: 0
A10: 6 | B10: Gabriel Magalhães | C10: 0 | D10: 6 | E10: Nayef Aguerd | F10: 0 | G10: 6 | H10: Ricardo Adé | I10: 0 | J10: 6 | K10: Andrew Robertson | L10: 0
A11: 7 | B11: Danilo | C11: 0 | D11: 7 | E11: Romain Saïss | F11: 0 | G11: 7 | H11: Duke Lacroix | I11: 0 | J11: 7 | K11: Scott McKenna | L11: 0
A12: 8 | B12: Wesley | C12: 0 | D12: 8 | E12: Jawad El Yamiq | F12: 0 | G12: 8 | H12: Garven Metusala | I12: 0 | J12: 8 | K12: John Souttar | L12: 0
A13: 9 | B13: Lucas Paquetá | C13: 0 | D13: 9 | E13: Adam Masina | F13: 0 | G13: 9 | H13: Hannes Delcroix | I13: 0 | J13: 9 | K13: Anthony Ralston | L13: 0
A14: 10 | B14: Casemiro | C14: 0 | D14: 10 | E14: Sofyan Amrabat | F14: 0 | G14: 10 | H14: Leverton Pierre | I14: 0 | J14: 10 | K14: Grant Hanley | L14: 0
A15: 11 | B15: Bruno Guimarães | C15: 0 | D15: 11 | E15: Azzedine Ounahi | F15: 0 | G15: 11 | H15: Danley Jean Jacques | I15: 0 | J15: 11 | K15: Scott McTominay | L15: 0
A16: 12 | B16: Luiz Henrique | C16: 0 | D16: 12 | E16: Eliesse Ben Seghir | F16: 0 | G16: 12 | H16: Jean-Ricner Bellegarde | I16: 0 | J16: 12 | K16: Billy Gilmour | L16: 0
... A24: 20 | B24: Estêvão | C24: 0 | D24: 20 | E24: Ayoub El Kaabi | F24: 0 | G24: 20 | H24: Frantzdy Pierrot | I24: 0 | J24: 20 | K24: Ben Gannon-Doak | L24: 0
A26: D | B26: D
B27: USA | E27: Paraguay | H27: Australia | K27: Türkiye
B28: USA | E28: PAR | H28: AUS | K28: TUR
A29: 1 | B29: Badge | C29: 0 | D29: 1 | E29: Badge | F29: 0 | G29: 1 | H29: Badge | I29: 0 | J29: 1 | K29: Badge | L29: 0
A30: 2 | B30: Matt Freese | C30: 0 | D30: 2 | E30: Roberto Fernández | F30: 0 | G30: 2 | H30: Mathew Ryan | I30: 0 | J30: 2 | K30: Uğurcan Çakır | L30: 0
A31: 3 | B31: Chris Richards | C31: 0 | D31: 3 | E31: Orlando Gill | F31: 0 | G31: 3 | H31: Joe Gauci | I31: 0 | J31: 3 | K31: Mert Müldür | L31: 0
A32: 4 | B32: Tim Ream | C32: 0 | D32: 4 | E32: Gustavo Gómez | F32: 0 | G32: 4 | H32: Harry Souttar | I32: 0 | J32: 4 | K32: Zeki Çelik | L32: 0
A33: 5 | B33: Mark McKenzie | C33: 0 | D33: 5 | E33: Fabián Balbuena | F33: 0 | G33: 5 | H33: Alessandro Circati | I33: 0 | J33: 5 | K33: Abdülkerim Bardakcı | L33: 0
A34: 6 | B34: Alex Freeman | C34: 0 | D34: 6 | E34: Juan José Cáceres | F34: 0 | G34: 6 | H34: Jordan Bos | I34: 0 | J34: 6 | K34: Çağlar Söyüncü | L34: 0
A35: 7 | B35: Antonee Robinson | C35: 0 | D35: 7 | E35: Omar Alderete | F35: 0 | G35: 7 | H35: Aziz Behich | I35: 0 | J35: 7 | K35: Merih Demiral | L35: 0
A36: 8 | B36: Tyler Adams | C36: 0 | D36: 8 | E36: Júnior Alonso | F36: 0 | G36: 8 | H36: Cameron Burgess | I36: 0 | J36: 8 | K36: Ferdi Kadıoğlu | L36: 0
A37: 9 | B37: Tanner Tessmann | C37: 0 | D37: 9 | E37: Mathías Villasanti | F37: 0 | G37: 9 | H37: Lewis Miller | I37: 0 | J37: 9 | K37: Kaan Ayhan | L37: 0
A38: 10 | B38: Weston McKennie | C38: 0 | D38: 10 | E38: Diego Gómez | F38: 0 | G38: 10 | H38: Milos Degenek | I38: 0 | J38: 10 | K38: İsmail Yüksek | L38: 0
A39: 11 | B39: Christian Roldan | C39: 0 | D39: 11 | E39: Damián Bobadilla | F39: 0 | G39: 11 | H39: Jackson Irvine | I39: 0 | J39: 11 | K39: Hakan Çalhanoğlu | L39: 0
A40: 12 | B40: Timothy Weah | C40: 0 | D40: 12 | E40: Andrés Cubas | F40: 0 | G40: 12 | H40: Riley McGree | I40: 0 | J40: 12 | K40: Orkun Kökçü | L40: 0
... A48: 20 | B48: Folarin Balogun | C48: 0 | D48: 20 | E48: Antonio Sanabria | F48: 0 | G48: 20 | H48: Mohamed Touré | I48: 0 | J48: 20 | K48: Kenan Yıldız | L48: 0

Sheet E-F
A2: E | B2: E
B3: Germany | E3: Curaçao | H3: Côte d’Ivoire | K3: Ecuador
B4: GER | E4: CUW | H4: CIV | K4: ECU
A5: 1 | B5: Badge | C5: 0 | D5: 1 | E5: Badge | F5: 0 | G5: 1 | H5: Badge | I5: 0 | J5: 1 | K5: Badge | L5: 0
A6: 2 | B6: Marc-André ter Stegen | C6: 0 | D6: 2 | E6: Eloy Room | F6: 0 | G6: 2 | H6: Yahia Fofana | I6: 0 | J6: 2 | K6: Hernán Galíndez | L6: 0
A7: 3 | B7: Jonathan Tah | C7: 0 | D7: 3 | E7: Armando Obispo | F7: 0 | G7: 3 | H7: Ghislain Konan | I7: 0 | J7: 3 | K7: Gonzalo Valle | L7: 0
A8: 4 | B8: David Raum | C8: 0 | D8: 4 | E8: Sherel Floranus | F8: 0 | G8: 4 | H8: Wilfried Singo | I8: 0 | J8: 4 | K8: Piero Hincapié | L8: 0
A9: 5 | B9: Nico Schlotterbeck | C9: 0 | D9: 5 | E9: Jurien Gaari | F9: 0 | G9: 5 | H9: Odilon Kossounou | I9: 0 | J9: 5 | K9: Pervis Estupiñán | L9: 0
A10: 6 | B10: Antonio Rüdiger | C10: 0 | D10: 6 | E10: Joshua Brenet | F10: 0 | G10: 6 | H10: Evan Ndicka | I10: 0 | J10: 6 | K10: Willian Pacho | L10: 0
A11: 7 | B11: Waldemar Anton | C11: 0 | D11: 7 | E11: Roshon van Eijma | F11: 0 | G11: 7 | H11: Willy Boly | I11: 0 | J11: 7 | K11: Ángelo Preciado | L11: 0
A12: 8 | B12: Ridle Baku | C12: 0 | D12: 8 | E12: Shurandy Sambo | F12: 0 | G12: 8 | H12: Emmanuel Agbadou | I12: 0 | J12: 8 | K12: Joel Ordóñez | L12: 0
A13: 9 | B13: Maximilian Mittelstädt | C13: 0 | D13: 9 | E13: Livano Comenencia | F13: 0 | G13: 9 | H13: Ousmane Diomande | I13: 0 | J13: 9 | K13: Moisés Caicedo | L13: 0
A14: 10 | B14: Joshua Kimmich | C14: 0 | D14: 10 | E14: Godfried Roemeratoe | F14: 0 | G14: 10 | H14: Franck Kessié | I14: 0 | J14: 10 | K14: Alan Franco | L14: 0
A15: 11 | B15: Florian Wirtz | C15: 0 | D15: 11 | E15: Juninho Bacuna | F15: 0 | G15: 11 | H15: Seko Fofana | I15: 0 | J15: 11 | K15: Kendry Páez | L15: 0
A16: 12 | B16: Felix Nmecha | C16: 0 | D16: 12 | E16: Leandro Bacuna | F16: 0 | G16: 12 | H16: Ibrahim Sangaré | I16: 0 | J16: 12 | K16: Pedro Vite | L16: 0
... A24: 20 | B24: Nick Woltemade | C24: 0 | D24: 20 | E24: Sontje Hansen | F24: 0 | G24: 20 | H24: Oumar Diakité | I24: 0 | J24: 20 | K24: Enner Valencia | L24: 0
A26: F | B26: F
B27: Netherlands | E27: Japan | H27: Sweden | K27: Tunisia
B28: NED | E28: JPN | H28: SWE | K28: TUN
A29: 1 | B29: Badge | C29: 0 | D29: 1 | E29: Badge | F29: 0 | G29: 1 | H29: Badge | I29: 0 | J29: 1 | K29: Badge | L29: 0
A30: 2 | B30: Bart Verbruggen | C30: 0 | D30: 2 | E30: Zion Suzuki | F30: 0 | G30: 2 | H30: Viktor Johansson | I30: 0 | J30: 2 | K30: Bechir Ben Said | L30: 0
A31: 3 | B31: Virgil van Dijk | C31: 0 | D31: 3 | E31: Henry Heroki Mochizuki | F31: 0 | G31: 3 | H31: Isak Hien | I31: 0 | J31: 3 | K31: Aymen Dahmen | L31: 0
A32: 4 | B32: Micky van de Ven | C32: 0 | D32: 4 | E32: Ayumu Seko | F32: 0 | G32: 4 | H32: Gabriel Gudmundsson | I32: 0 | J32: 4 | K32: Yan Valery | L32: 0
A33: 5 | B33: Jurrien Timber | C33: 1 | D33: 5 | E33: Junnosuke Suzuki | F33: 0 | G33: 5 | H33: Emil Holm | I33: 0 | J33: 5 | K33: Montassar Talbi | L33: 0
A34: 6 | B34: Denzel Dumfries | C34: 0 | D34: 6 | E34: Shogo Taniguchi | F34: 0 | G34: 6 | H34: Victor Nilsson Lindelöf | I34: 0 | J34: 6 | K34: Yassine Meriah | L34: 0
A35: 7 | B35: Nathan Aké | C35: 0 | D35: 7 | E35: Tsuyoshi Watanabe | F35: 0 | G35: 7 | H35: Gustaf Lagerbielke | I35: 0 | J35: 7 | K35: Ali Abdi | L35: 0
A36: 8 | B36: Jeremie Frimpong | C36: 0 | D36: 8 | E36: Kaishu Sano | F36: 0 | G36: 8 | H36: Lucas Bergvall | I36: 0 | J36: 8 | K36: Dylan Bronn | L36: 0
A37: 9 | B37: Jan Paul van Hecke | C37: 0 | D37: 9 | E37: Yuki Soma | F37: 0 | G37: 9 | H37: Hugo Larsson | I37: 0 | J37: 9 | K37: Ellyes Skhiri | L37: 0
A38: 10 | B38: Tijjani Reijnders | C38: 0 | D38: 10 | E38: Ao Tanaka | F38: 0 | G38: 10 | H38: Jesper Karlström | I38: 0 | J38: 10 | K38: Aïssa Laïdouni | L38: 0
A39: 11 | B39: Ryan Gravenberch | C39: 0 | D39: 11 | E39: Daichi Kamada | F39: 0 | G39: 11 | H39: Yasin Ayari | I39: 0 | J39: 11 | K39: Ferjani Sassi | L39: 0
A40: 12 | B40: Teun Koopmeiners | C40: 0 | D40: 12 | E40: Takefusa Kubo | F40: 0 | G40: 12 | H40: Mattias Svanberg | I40: 0 | J40: 12 | K40: Mohamed Ali Ben Romdhane | L40: 0
... A48: 20 | B48: Cody Gakpo | C48: 0 | D48: 20 | E48: Ayase Ueda | F48: 0 | G48: 20 | H48: Viktor Gyökeres | I48: 0 | J48: 20 | K48: Naïm Sliti | L48: 0

Sheet G-H
A2: G | B2: G
B3: Belgium | E3: Egypt | H3: IR Iran | K3: New Zealand
B4: BEL | E4: EGY | H4: IRN | K4: NZL
A5: 1 | B5: Badge | C5: 0 | D5: 1 | E5: Badge | F5: 0 | G5: 1 | H5: Badge | I5: 0 | J5: 1 | K5: Badge | L5: 0
A6: 2 | B6: Thibaut Courtois | C6: 0 | D6: 2 | E6: Mohamed El Shenawy | F6: 0 | G6: 2 | H6: Alireza Beiranvand | I6: 0 | J6: 2 | K6: Max Crocombe | L6: 0
A7: 3 | B7: Arthur Theate | C7: 0 | D7: 3 | E7: Mohamed Hany | F7: 0 | G7: 3 | H7: Morteza Pouraliganji | I7: 0 | J7: 3 | K7: Alex Paulsen | L7: 0
A8: 4 | B8: Timothy Castagne | C8: 0 | D8: 4 | E8: Mohamed Hamdy | F8: 0 | G8: 4 | H8: Ehsan Hajsafi | I8: 0 | J8: 4 | K8: Michael Boxall | L8: 0
A9: 5 | B9: Zeno Debast | C9: 0 | D9: 5 | E9: Yasser Ibrahim | F9: 0 | G9: 5 | H9: Milad Mohammadi | I9: 0 | J9: 5 | K9: Liberato Cacace | L9: 0
A10: 6 | B10: Brandon Mechele | C10: 0 | D10: 6 | E10: Khaled Sobhi | F10: 0 | G10: 6 | H10: Shojae Khalilzadeh | I10: 0 | J10: 6 | K10: Tim Payne | L10: 0
A11: 7 | B11: Maxim De Cuyper | C11: 0 | D11: 7 | E11: Ramy Rabia | F11: 0 | G11: 7 | H11: Ramin Rezaeian | I11: 0 | J11: 7 | K11: Tyler Bindon | L11: 0
A12: 8 | B12: Thomas Meunier | C12: 0 | D12: 8 | E12: Hossam Abdelmaguid | F12: 0 | G12: 8 | H12: Hossein Kanaani | I12: 0 | J12: 8 | K12: Francis de Vries | L12: 0
A13: 9 | B13: Youri Tielemans | C13: 0 | D13: 9 | E13: Ahmed Fatouh | F13: 0 | G13: 9 | H13: Sadegh Moharrami | I13: 0 | J13: 9 | K13: Finn Surman | L13: 0
A14: 10 | B14: Amadou Onana | C14: 0 | D14: 10 | E14: Marwan Attia | F14: 0 | G14: 10 | H14: Saleh Hardani | I14: 0 | J14: 10 | K14: Joe Bell | L14: 0
A15: 11 | B15: Nicolas Raskin | C15: 0 | D15: 11 | E15: Zizo | F15: 0 | G15: 11 | H15: Saeed Ezatolahi | I15: 0 | J15: 11 | K15: Sarpreet Singh | L15: 0
A16: 12 | B16: Alexis Saelemaekers | C16: 0 | D16: 12 | E16: Hamdy Fathy | F16: 0 | G16: 12 | H16: Saman Ghoddos | I16: 0 | J16: 12 | K16: Ryan Thomas | L16: 0
... A24: 20 | B24: Romelu Lukaku | C24: 0 | D24: 20 | E24: Omar Marmoush | F24: 0 | G24: 20 | H24: Ali Gholizadeh | I24: 0 | J24: 20 | K24: Kosta Barbarouses | L24: 0
A26: H | B26: H
B27: Spain | E27: Cabo Verde | H27: Saudi Arabia | K27: Uruguay
B28: ESP | E28: CPV | H28: KSA | K28: URU
A29: 1 | B29: Badge | C29: 0 | D29: 1 | E29: Badge | F29: 0 | G29: 1 | H29: Badge | I29: 0 | J29: 1 | K29: Badge | L29: 0
A30: 2 | B30: Unai Simón | C30: 0 | D30: 2 | E30: Vozinha | F30: 0 | G30: 2 | H30: Nawaf Alaqidi | I30: 0 | J30: 2 | K30: Sergio Rochet | L30: 0
A31: 3 | B31: Robin Le Normand | C31: 0 | D31: 3 | E31: Logan Costa | F31: 0 | G31: 3 | H31: Abdulrahman Al-Sanbi | I31: 0 | J31: 3 | K31: Santiago Mele | L31: 0
A32: 4 | B32: Aymeric Laporte | C32: 0 | D32: 4 | E32: Pico | F32: 0 | G32: 4 | H32: Saud Abdulhamid | I32: 0 | J32: 4 | K32: Ronald Araújo | L32: 0
A33: 5 | B33: Dean Huijsen | C33: 0 | D33: 5 | E33: Diney | F33: 0 | G33: 5 | H33: Nawaf Boushal | I33: 0 | J33: 5 | K33: José María Giménez | L33: 0
A34: 6 | B34: Pedro Porro | C34: 0 | D34: 6 | E34: Steven Moreira | F34: 0 | G34: 6 | H34: Jihad Thakri | I34: 0 | J34: 6 | K34: Sebastián Cáceres | L34: 0
A35: 7 | B35: Dani Carvajal | C35: 0 | D35: 7 | E35: Wagner Pina | F35: 0 | G35: 7 | H35: Moteb Al-Harbi | I35: 0 | J35: 7 | K35: Mathías Olivera | L35: 0
A36: 8 | B36: Marc Cucurella | C36: 0 | D36: 8 | E36: João Paulo | F36: 0 | G36: 8 | H36: Hassan Altambakti | I36: 0 | J36: 8 | K36: Guillermo Varela | L36: 0
A37: 9 | B37: Martín Zubimendi | C37: 0 | D37: 9 | E37: Yannick Semedo | F37: 0 | G37: 9 | H37: Musab Aljuwayr | I37: 0 | J37: 9 | K37: Nahitan Nández | L37: 0
A38: 10 | B38: Rodri | C38: 0 | D38: 10 | E38: Kevin Pina | F38: 0 | G38: 10 | H38: Ziyad Aljohani | I38: 0 | J38: 10 | K38: Federico Valverde | L38: 0
A39: 11 | B39: Pedri | C39: 0 | D39: 11 | E39: Patrick Andrade | F39: 0 | G39: 11 | H39: Abdullah Alkhaibari | I39: 0 | J39: 11 | K39: Giorgian De Arrascaeta | L39: 0
A40: 12 | B40: Fabián Ruiz | C40: 0 | D40: 12 | E40: Jamiro Monteiro | F40: 0 | G40: 12 | H40: Nasser Aldawsari | I40: 0 | J40: 12 | K40: Rodrigo Bentancur | L40: 0
... A48: 20 | B48: Mikel Oyarzabal | C48: 0 | D48: 20 | E48: Bebé | F48: 0 | G48: 20 | H48: Abdullah Al-Hamdan | I48: 0 | J48: 20 | K48: Facundo Pellistri | L48: 0

Sheet I-J
A2: I | B2: I
B3: France | E3: Senegal | H3: Iraq | K3: Norway
B4: FRA | E4: SEN | H4: IRQ | K4: NOR
A5: 1 | B5: Badge | C5: 0 | D5: 1 | E5: Badge | F5: 0 | G5: 1 | H5: Badge | I5: 0 | J5: 1 | K5: Badge | L5: 0
A6: 2 | B6: Mike Maignan | C6: 0 | D6: 2 | E6: Edouard Mendy | F6: 0 | G6: 2 | H6: Jalal Hassan | I6: 0 | J6: 2 | K6: Ørjan Nyland | L6: 0
A7: 3 | B7: Théo Hernandez | C7: 0 | D7: 3 | E7: Yehvann Diouf | F7: 0 | G7: 3 | H7: Rebin Sulaka | I7: 0 | J7: 3 | K7: Julian Ryerson | L7: 0
A8: 4 | B8: William Saliba | C8: 0 | D8: 4 | E8: Moussa Niakhaté | F8: 0 | G8: 4 | H8: Hussein Ali | I8: 0 | J8: 4 | K8: Leo Østigård | L8: 0
A9: 5 | B9: Jules Koundé | C9: 0 | D9: 5 | E9: Abdoulaye Seck | F9: 0 | G9: 5 | H9: Akam Hashem | I9: 0 | J9: 5 | K9: Kristoffer Vassbakk Ajer | L9: 0
A10: 6 | B10: Ibrahima Konaté | C10: 0 | D10: 6 | E10: Ismail Jakobs | F10: 0 | G10: 6 | H10: Merchas Doski | I10: 0 | J10: 6 | K10: Marcus Holmgren Pedersen | L10: 0
A11: 7 | B11: Dayot Upamecano | C11: 0 | D11: 7 | E11: El Hadji Malick Diouf | F11: 0 | G11: 7 | H11: Zaid Tahseen | I11: 0 | J11: 7 | K11: David Møller Wolfe | L11: 0
A12: 8 | B12: Lucas Digne | C12: 0 | D12: 8 | E12: Kalidou Koulibaly | F12: 0 | G12: 8 | H12: Manaf Younis | I12: 0 | J12: 8 | K12: Torbjørn Heggem | L12: 0
A13: 9 | B13: Aurélien Tchouaméni | C13: 0 | D13: 9 | E13: Idrissa Gana Gueye | F13: 0 | G13: 9 | H13: Zidane Iqbal | I13: 0 | J13: 9 | K13: Morten Thorsby | L13: 0
A14: 10 | B14: Eduardo Camavinga | C14: 0 | D14: 10 | E14: Pape Matar Sarr | F14: 0 | G14: 10 | H14: Amir Al-Ammari | I14: 0 | J14: 10 | K14: Martin Ødegaard | L14: 0
A15: 11 | B15: Manu Koné | C15: 0 | D15: 11 | E15: Pape Gueye | F15: 0 | G15: 11 | H15: Ibrahim Bayesh | I15: 0 | J15: 11 | K15: Sander Berge | L15: 0
A16: 12 | B16: Adrien Rabiot | C16: 0 | D16: 12 | E16: Habib Diarra | F16: 0 | G16: 12 | H16: Ali Jasim | I16: 0 | J16: 12 | K16: Andreas Schjelderup | L16: 0
... A24: 20 | B24: Kylian Mbappé | C24: 0 | D24: 20 | E24: Krépin Diatta | F24: 0 | G24: 20 | H24: Mohanad Ali | I24: 0 | J24: 20 | K24: Oscar Bobb | L24: 0
A26: J | B26: J
B27: Argentina | E27: Algeria | H27: Austria | K27: Jordan
B28: ARG | E28: ALG | H28: AUT | K28: JOR
A29: 1 | B29: Badge | C29: 0 | D29: 1 | E29: Badge | F29: 0 | G29: 1 | H29: Badge | I29: 0 | J29: 1 | K29: Badge | L29: 0
A30: 2 | B30: Emiliano Martínez | C30: 0 | D30: 2 | E30: Alexis Guendouz | F30: 0 | G30: 2 | H30: Alexander Schlager | I30: 0 | J30: 2 | K30: Yazeed Abulaila | L30: 0
A31: 3 | B31: Nahuel Molina | C31: 0 | D31: 3 | E31: Ramy Bensebaini | F31: 0 | G31: 3 | H31: Patrick Pentz | I31: 0 | J31: 3 | K31: Ihsan Haddad | L31: 0
A32: 4 | B32: Cristian Romero | C32: 0 | D32: 4 | E32: Youcef Atal | F32: 0 | G32: 4 | H32: David Alaba | I32: 0 | J32: 4 | K32: Mohammad Abu Hashish | L32: 0
A33: 5 | B33: Nicolás Otamendi | C33: 0 | D33: 5 | E33: Rayan Aït-Nouri | F33: 0 | G33: 5 | H33: Kevin Danso | I33: 0 | J33: 5 | K33: Yazan Al-Arab | L33: 0
A34: 6 | B34: Nicolás Tagliafico | C34: 0 | D34: 6 | E34: Mohamed Amine Tougaï | F34: 0 | G34: 6 | H34: Philipp Lienhart | I34: 0 | J34: 6 | K34: Abdallah Nasib | L34: 0
A35: 7 | B35: Leonardo Balerdi | C35: 0 | D35: 7 | E35: Aïssa Mandi | F35: 0 | G35: 7 | H35: Stefan Posch | I35: 0 | J35: 7 | K35: Saleem Obaid | L35: 0
A36: 8 | B36: Enzo Fernández | C36: 0 | D36: 8 | E36: Ismaël Bennacer | F36: 0 | G36: 8 | H36: Philipp Mwene | I36: 0 | J36: 8 | K36: Mohammad Abualnadi | L36: 0
A37: 9 | B37: Alexis Mac Allister | C37: 0 | D37: 9 | E37: Houssem Aouar | F37: 0 | G37: 9 | H37: Alexander Prass | I37: 0 | J37: 9 | K37: Ibrahim Saadeh | L37: 0
A38: 10 | B38: Rodrigo De Paul | C38: 0 | D38: 10 | E38: Hicham Boudaoui | F38: 0 | G38: 10 | H38: Xaver Schlager | I38: 0 | J38: 10 | K38: Nizar Al-Rashdan | L38: 0
A39: 11 | B39: Exequiel Palacios | C39: 0 | D39: 11 | E39: Ramiz Zerrouki | F39: 0 | G39: 11 | H39: Marcel Sabitzer | I39: 0 | J39: 11 | K39: Noor Al-Rawabdeh | L39: 0
A40: 12 | B40: Leandro Paredes | C40: 0 | D40: 12 | E40: Nabil Bentaleb | F40: 0 | G40: 12 | H40: Konrad Laimer | I40: 0 | J40: 12 | K40: Mohannad Abu Taha | L40: 0
... A48: 20 | B48: Giuliano Simeone | C48: 0 | D48: 20 | E48: Mohamed Amoura | F48: 0 | G48: 20 | H48: Marko Arnautović | I48: 0 | J48: 20 | K48: Ibrahim Sabra | L48: 0

Sheet K-L
A1: k
A2: K | B2: K
B3: Portugal | E3: Congo DR | H3: Uzbekistan | K3: Colombia
B4: POR | E4: COD | H4: UZB | K4: COL
A5: 1 | B5: Badge | C5: 0 | D5: 1 | E5: Badge | F5: 0 | G5: 1 | H5: Badge | I5: 0 | J5: 1 | K5: Badge | L5: 0
A6: 2 | B6: Diogo Costa | C6: 0 | D6: 2 | E6: Lionel Mpasi | F6: 0 | G6: 2 | H6: Utkir Yusupov | I6: 0 | J6: 2 | K6: Camilo Vargas | L6: 0
A7: 3 | B7: José Sá | C7: 0 | D7: 3 | E7: Aaron Wan-Bissaka | F7: 0 | G7: 3 | H7: Farrukh Sayfiev | I7: 0 | J7: 3 | K7: David Ospina | L7: 0
A8: 4 | B8: Rúben Dias | C8: 0 | D8: 4 | E8: Axel Tuanzebe | F8: 0 | G8: 4 | H8: Sherzod Nasrullaev | I8: 0 | J8: 4 | K8: Davinson Sánchez | L8: 0
A9: 5 | B9: João Cancelo | C9: 0 | D9: 5 | E9: Arthur Masuaku | F9: 0 | G9: 5 | H9: Umar Eshmurodov | I9: 0 | J9: 5 | K9: Yerry Mina | L9: 0
A10: 6 | B10: Diogo Dalot | C10: 0 | D10: 6 | E10: Chancel Mbemba | F10: 0 | G10: 6 | H10: Husniddin Aliqulov | I10: 0 | J10: 6 | K10: Daniel Muñoz | L10: 0
A11: 7 | B11: Nuno Mendes | C11: 0 | D11: 7 | E11: Joris Kayembe | F11: 0 | G11: 7 | H11: Rustamjon Ashurmatov | I11: 0 | J11: 7 | K11: Johan Mojica | L11: 0
A12: 8 | B12: Gonçalo Inácio | C12: 0 | D12: 8 | E12: Charles Pickel | F12: 0 | G12: 8 | H12: Khojiakbar Alijonov | I12: 0 | J12: 8 | K12: Jhon Lucumí | L12: 0
A13: 9 | B13: Bernardo Silva | C13: 0 | D13: 9 | E13: Ngal'ayel Mukau | F13: 0 | G13: 9 | H13: Abdukodir Khusanov | I13: 0 | J13: 9 | K13: Santiago Arias | L13: 0
A14: 10 | B14: Bruno Fernandes | C14: 0 | D14: 10 | E14: Edo Kayembe | F14: 0 | G14: 10 | H14: Odiljon Hamrobekov | I14: 0 | J14: 10 | K14: Jefferson Lerma | L14: 0
A15: 11 | B15: Rúben Neves | C15: 0 | D15: 11 | E15: Samuel Moutoussamy | F15: 0 | G15: 11 | H15: Otabek Shukurov | I15: 0 | J15: 11 | K15: Kevin Castaño | L15: 0
A16: 12 | B16: Vitinha | C16: 0 | D16: 12 | E16: Noah Sadiki | F16: 0 | G16: 12 | H16: Jamshid Iskanderov | I16: 0 | J16: 12 | K16: Richard Ríos | L16: 0
... A24: 20 | B24: Rafael Leão | C24: 0 | D24: 20 | E24: Nathanaël Mbuku | F24: 0 | G24: 20 | H24: Abbosbek Fayzullaev | I24: 0 | J24: 20 | K24: Luis Díaz | L24: 0
A26: L | B26: L
B27: England | E27: Croatia | H27: Ghana | K27: Panama
B28: ENG | E28: CRO | H28: GHA | K28: PAN
A29: 1 | B29: Badge | C29: 0 | D29: 1 | E29: Badge | F29: 0 | G29: 1 | H29: Badge | I29: 0 | J29: 1 | K29: Badge | L29: 0
A30: 2 | B30: Jordan Pickford | C30: 0 | D30: 2 | E30: Dominik Livaković | F30: 0 | G30: 2 | H30: Lawrence Ati Zigi | I30: 0 | J30: 2 | K30: Orlando Mosquera | L30: 0
A31: 3 | B31: John Stones | C31: 0 | D31: 3 | E31: Duje Ćaleta-Car | F31: 0 | G31: 3 | H31: Tariq Lamptey | I31: 0 | J31: 3 | K31: Luis Mejía | L31: 0
A32: 4 | B32: Marc Guéhi | C32: 0 | D32: 4 | E32: Joško Gvardiol | F32: 0 | G32: 4 | H32: Mohammed Salisu | I32: 0 | J32: 4 | K32: Fidel Escobar | L32: 0
A33: 5 | B33: Ezri Konsa | C33: 0 | D33: 5 | E33: Josip Stanišić | F33: 0 | G33: 5 | H33: Alidu Seidu | I33: 0 | J33: 5 | K33: Andrés Andrade | L33: 0
A34: 6 | B34: Trent Alexander-Arnold | C34: 0 | D34: 6 | E34: Luka Vušković | F34: 0 | G34: 6 | H34: Alexander Djiku | I34: 1 | J34: 6 | K34: Michael Amir Murillo | L34: 0
A35: 7 | B35: Reece James | C35: 0 | D35: 7 | E35: Josip Šutalo | F35: 0 | G35: 7 | H35: Gideon Mensah | I35: 0 | J35: 7 | K35: Eric Davis | L35: 0
A36: 8 | B36: Dan Burn | C36: 0 | D36: 8 | E36: Kristijan Jakić | F36: 0 | G36: 8 | H36: Caleb Yirenkyi | I36: 0 | J36: 8 | K36: José Córdoba | L36: 0
A37: 9 | B37: Jordan Henderson | C37: 0 | D37: 9 | E37: Luka Modrić | F37: 0 | G37: 9 | H37: Abdul Issahaku Fatawu | I37: 0 | J37: 9 | K37: César Blackman | L37: 0
A38: 10 | B38: Declan Rice | C38: 0 | D38: 10 | E38: Mateo Kovačić | F38: 0 | G38: 10 | H38: Thomas Partey | I38: 0 | J38: 10 | K38: Cristian Martínez | L38: 0
A39: 11 | B39: Jude Bellingham | C39: 0 | D39: 11 | E39: Martin Baturina | F39: 0 | G39: 11 | H39: Salis Abdul Samed | I39: 0 | J39: 11 | K39: Aníbal Godoy | L39: 0
A40: 12 | B40: Cole Palmer | C40: 0 | D40: 12 | E40: Lovro Majer | F40: 0 | G40: 12 | H40: Kamaldeen Sulemana | I40: 0 | J40: 12 | K40: Adalberto Carrasquilla | L40: 0
... A48: 20 | B48: Ollie Watkins | C48: 0 | D48: 20 | E48: Franjo Ivanović | F48: 0 | G48: 20 | H48: Antoine Semenyo | I48: 0 | J48: 20 | K48: Alberto Quintero | L48: 0

Sheet Others
A2: 00 | D2: FIFA World Cup History | H2: Coca-Cola
A3: 00 | B3: 0 | D3: FWC1 | E3: Official Emblem | F3: 0 | H3: CC1 | I3: Lamine Yamal | J3: 0
D4: FWC2 | E4: Official Emblem | F4: 0 | H4: CC2 | I4: Joshua Kimmich | J4: 0
D5: FWC3 | E5: Official Mascots | F5: 0 | H5: CC3 | I5: Eduardo Camavinga | J5: 0
D6: FWC4 | E6: Official Slogan | F6: 0 | H6: CC4 | I6: Josko Vardiol | J6: 0
D7: FWC5 | E7: Official Ball | F7: 0 | H7: CC5 | I7: Federico Valverde | J7: 0
D8: FWC6 | E8: Host Country Emblem | F8: 0 | H8: CC6 | I8: Virgil van Dijk | J8: 0
D9: FWC7 | E9: Host Country Emblem | F9: 0 | H9: CC7 | I9: Alphonso Davies | J9: 0
D10: FWC8 | E10: Host Country Emblem | F10: 0 | H10: CC8 | I10: Raul Jimenez | J10: 0
D11: FWC9 | E11: FIFA World Cup Italy 1934 | F11: 0 | H11: CC9 | I11: William Saliba | J11: 0
D12: FWC10 | E12: FIFA World Cup Brazil 1950 | F12: 0 | H12: CC10 | I12: Lautaro mArtinez | J12: 0
D13: FWC11 | E13: FIFA World Cup Switzerland 1954 | F13: 0 | H13: CC11 | I13: Harry Kane | J13: 0
D14: FWC12 | E14: FIFA World Cup Chile 1962 | F14: 0 | H14: CC12 | I14: Antonee Robinson | J14: 0
D15: FWC13 | E15: FIFA World Cup Germany 1974 | F15: 0
D16: FWC14 | E16: FIFA World Cup Mexico 1986 | F16: 0
D17: FWC15 | E17: FIFA World Cup USA 1994 | F17: 0
D18: FWC16 | E18: FIFA World Cup Korea-Japan 2002 | F18: 0
D19: FWC17 | E19: FIFA World Cup Germany 2006 | F19: 0
D20: FWC18 | E20: FIFA World Cup Brazil 2014 | F20: 0
D21: FWC19 | E21: FIFA World Cup Qatar 2022 | F21: 0

Sheet Missing Stickers
A1: Missing Stickers
A2: Group | B2: Team | C2: Shortcut
A3: A | B3: Mexico | C3: MEX | D3: {=IF($B3="Other",_xlfn.LET(_xlpm.num,IFERROR(--Others!$B$3,0),IF(_xlpm.num<1,Summary!D3,"")),IF($C3="FWC",_xlfn.LET(_xlpm.codes,_xlfn._xlws.FILTER(Summary!D3:W3,Summary!D3:W3<>""),_xlpm.nums,TRANSPOSE(IFERROR(--Others!$F$3:$F$21,0)),IFERROR(_xlfn.TEXTJOIN(", ",TRUE,_xlfn._xlws.FILTER(_xlpm.codes,_xlpm.nums<1)),"")),IF($C3="CC",_xlfn.LET(_xlpm.codes,_xlfn._xlws.FILTER(Summary!D3:W3,Summary!D3:W3<>""),_xlpm.nums,TRANSPOSE(IFERROR(--Others!$J$3:$J$14,0)),IFERROR(_xlfn.TEXTJOIN(", ",TRUE,_xlfn._xlws.FILTER(_xlpm.codes,_xlpm.nums<1)),"")),IF($C3="","",_xlfn.LET(_xlpm.idx,COUNTIF($C$3:INDEX($C:$C,ROW()),"<>"),_xlpm.grpNo,ROUNDUP(_xlpm.idx/4,0),_xlpm.sh,CHOOSE(ROUNDUP(_xlpm.grpNo/2,0),"A-B","C-D","E-F","G-H","I-J","K-L"),_xlpm.startRow,IF(ISODD(_xlpm.grpNo),5,29),_xlpm.teamNo,MOD(_xlpm.idx-1,4)+1,_xlpm.counts,CHOOSE(_xlpm.teamNo,INDIRECT("'"&_xlpm.sh&"'!C"&_xlpm.startRow&":C"&(_xlpm.startRow+19)),INDIRECT("'"&_xlpm.sh&"'!F"&_xlpm.startRow&":F"&(_xlpm.startRow+19)),INDIRECT("'"&_xlpm.sh&"'!I"&_xlpm.startRow&":I"&(_xlpm.startRow+19)),INDIRECT("'"&_xlpm.sh&"'!L"&_xlpm.startRow&":L"&(_xlpm.startRow+19))),_xlpm.nums,TRANSPOSE(IFERROR(--_xlpm.counts,0)),_xlpm.codes,Summary!D3:W3,IFERROR(_xlfn.TEXTJOIN(", ",TRUE,_xlfn._xlws.FILTER(_xlpm.codes,_xlpm.nums<1)),""))))))} -> MEX 1, MEX 2, MEX 3, MEX 4, MEX 5, MEX 6, MEX 7, MEX 8, MEX 9, MEX 10, MEX 11, MEX 12, MEX 13, MEX 14, MEX 15, MEX 16, MEX 17, MEX 18, MEX 19, MEX 20
A4: A | B4: South Africa | C4: RSA | D4: {=IF($B4="Other",_xlfn.LET(_xlpm.num,IFERROR(--Others!$B$3,0),IF(_xlpm.num<1,Summary!D4,"")),IF($C4="FWC",_xlfn.LET(_xlpm.codes,_xlfn._xlws.FILTER(Summary!D4:W4,Summary!D4:W4<>""),_xlpm.nums,TRANSPOSE(IFERROR(--Others!$F$3:$F$21,0)),IFERROR(_xlfn.TEXTJOIN(", ",TRUE,_xlfn._xlws.FILTER(_xlpm.codes,_xlpm.nums<1)),"")),IF($C4="CC",_xlfn.LET(_xlpm.codes,_xlfn._xlws.FILTER(Summary!D4:W4,Summary!D4:W4<>""),_xlpm.nums,TRANSPOSE(IFERROR(--Others!$J$3:$J$14,0)),IFERROR(_xlfn.TEXTJOIN(", ",TRUE,_xlfn._xlws.FILTER(_xlpm.codes,_xlpm.nums<1)),"")),IF($C4="","",_xlfn.LET(_xlpm.idx,COUNTIF($C$3:INDEX($C:$C,ROW()),"<>"),_xlpm.grpNo,ROUNDUP(_xlpm.idx/4,0),_xlpm.sh,CHOOSE(ROUNDUP(_xlpm.grpNo/2,0),"A-B","C-D","E-F","G-H","I-J","K-L"),_xlpm.startRow,IF(ISODD(_xlpm.grpNo),5,29),_xlpm.teamNo,MOD(_xlpm.idx-1,4)+1,_xlpm.counts,CHOOSE(_xlpm.teamNo,INDIRECT("'"&_xlpm.sh&"'!C"&_xlpm.startRow&":C"&(_xlpm.startRow+19)),INDIRECT("'"&_xlpm.sh&"'!F"&_xlpm.startRow&":F"&(_xlpm.startRow+19)),INDIRECT("'"&_xlpm.sh&"'!I"&_xlpm.startRow&":I"&(_xlpm.startRow+19)),INDIRECT("'"&_xlpm.sh&"'!L"&_xlpm.startRow&":L"&(_xlpm.startRow+19))),_xlpm.nums,TRANSPOSE(IFERROR(--_xlpm.counts,0)),_xlpm.codes,Summary!D4:W4,IFERROR(_xlfn.TEXTJOIN(", ",TRUE,_xlfn._xlws.FILTER(_xlpm.codes,_xlpm.nums<1)),""))))))} -> RSA 1, RSA 2, RSA 3, RSA 4, RSA 5, RSA 6, RSA 7, RSA 8, RSA 9, RSA 10, RSA 11, RSA 12, RSA 13, RSA 14, RSA 15, RSA 16, RSA 17, RSA 18, RSA 19, RSA 20
A5: A | B5: Korea Republic | C5: KOR | D5: {=IF($B5="Other",_xlfn.LET(_xlpm.num,IFERROR(--Others!$B$3,0),IF(_xlpm.num<1,Summary!D5,"")),IF($C5="FWC",_xlfn.LET(_xlpm.codes,_xlfn._xlws.FILTER(Summary!D5:W5,Summary!D5:W5<>""),_xlpm.nums,TRANSPOSE(IFERROR(--Others!$F$3:$F$21,0)),IFERROR(_xlfn.TEXTJOIN(", ",TRUE,_xlfn._xlws.FILTER(_xlpm.codes,_xlpm.nums<1)),"")),IF($C5="CC",_xlfn.LET(_xlpm.codes,_xlfn._xlws.FILTER(Summary!D5:W5,Summary!D5:W5<>""),_xlpm.nums,TRANSPOSE(IFERROR(--Others!$J$3:$J$14,0)),IFERROR(_xlfn.TEXTJOIN(", ",TRUE,_xlfn._xlws.FILTER(_xlpm.codes,_xlpm.nums<1)),"")),IF($C5="","",_xlfn.LET(_xlpm.idx,COUNTIF($C$3:INDEX($C:$C,ROW()),"<>"),_xlpm.grpNo,ROUNDUP(_xlpm.idx/4,0),_xlpm.sh,CHOOSE(ROUNDUP(_xlpm.grpNo/2,0),"A-B","C-D","E-F","G-H","I-J","K-L"),_xlpm.startRow,IF(ISODD(_xlpm.grpNo),5,29),_xlpm.teamNo,MOD(_xlpm.idx-1,4)+1,_xlpm.counts,CHOOSE(_xlpm.teamNo,INDIRECT("'"&_xlpm.sh&"'!C"&_xlpm.startRow&":C"&(_xlpm.startRow+19)),INDIRECT("'"&_xlpm.sh&"'!F"&_xlpm.startRow&":F"&(_xlpm.startRow+19)),INDIRECT("'"&_xlpm.sh&"'!I"&_xlpm.startRow&":I"&(_xlpm.startRow+19)),INDIRECT("'"&_xlpm.sh&"'!L"&_xlpm.startRow&":L"&(_xlpm.startRow+19))),_xlpm.nums,TRANSPOSE(IFERROR(--_xlpm.counts,0)),_xlpm.codes,Summary!D5:W5,IFERROR(_xlfn.TEXTJOIN(", ",TRUE,_xlfn._xlws.FILTER(_xlpm.codes,_xlpm.nums<1)),""))))))} -> KOR 1, KOR 2, KOR 3, KOR 4, KOR 5, KOR 6, KOR 7, KOR 8, KOR 9, KOR 10, KOR 11, KOR 12, KOR 13, KOR 14, KOR 15, KOR 16, KOR 17, KOR 18, KOR 19, KOR 20
A6: A | B6: Czechia | C6: CZE | D6: {=IF($B6="Other",_xlfn.LET(_xlpm.num,IFERROR(--Others!$B$3,0),IF(_xlpm.num<1,Summary!D6,"")),IF($C6="FWC",_xlfn.LET(_xlpm.codes,_xlfn._xlws.FILTER(Summary!D6:W6,Summary!D6:W6<>""),_xlpm.nums,TRANSPOSE(IFERROR(--Others!$F$3:$F$21,0)),IFERROR(_xlfn.TEXTJOIN(", ",TRUE,_xlfn._xlws.FILTER(_xlpm.codes,_xlpm.nums<1)),"")),IF($C6="CC",_xlfn.LET(_xlpm.codes,_xlfn._xlws.FILTER(Summary!D6:W6,Summary!D6:W6<>""),_xlpm.nums,TRANSPOSE(IFERROR(--Others!$J$3:$J$14,0)),IFERROR(_xlfn.TEXTJOIN(", ",TRUE,_xlfn._xlws.FILTER(_xlpm.codes,_xlpm.nums<1)),"")),IF($C6="","",_xlfn.LET(_xlpm.idx,COUNTIF($C$3:INDEX($C:$C,ROW()),"<>"),_xlpm.grpNo,ROUNDUP(_xlpm.idx/4,0),_xlpm.sh,CHOOSE(ROUNDUP(_xlpm.grpNo/2,0),"A-B","C-D","E-F","G-H","I-J","K-L"),_xlpm.startRow,IF(ISODD(_xlpm.grpNo),5,29),_xlpm.teamNo,MOD(_xlpm.idx-1,4)+1,_xlpm.counts,CHOOSE(_xlpm.teamNo,INDIRECT("'"&_xlpm.sh&"'!C"&_xlpm.startRow&":C"&(_xlpm.startRow+19)),INDIRECT("'"&_xlpm.sh&"'!F"&_xlpm.startRow&":F"&(_xlpm.startRow+19)),INDIRECT("'"&_xlpm.sh&"'!I"&_xlpm.startRow&":I"&(_xlpm.startRow+19)),INDIRECT("'"&_xlpm.sh&"'!L"&_xlpm.startRow&":L"&(_xlpm.startRow+19))),_xlpm.nums,TRANSPOSE(IFERROR(--_xlpm.counts,0)),_xlpm.codes,Summary!D6:W6,IFERROR(_xlfn.TEXTJOIN(", ",TRUE,_xlfn._xlws.FILTER(_xlpm.codes,_xlpm.nums<1)),""))))))} -> CZE 1, CZE 2, CZE 3, CZE 4, CZE 5, CZE 6, CZE 7, CZE 8, CZE 9, CZE 10, CZE 11, CZE 12, CZE 13, CZE 14, CZE 15, CZE 16, CZE 17, CZE 18, CZE 19, CZE 20
D7: {=IF($C7="","",_xlfn.LET(_xlpm.grp,$A7,_xlpm.sh,CHOOSE(ROUNDUP((CODE(_xlpm.grp)-64)/2,0),"A-B","C-D","E-F","G-H","I-J","K-L"),_xlpm.startRow,IF(ISODD(CODE(_xlpm.grp)-64),5,29),_xlpm.teamNo,COUNTIF($A$3:$A7,_xlpm.grp),_xlpm.counts,CHOOSE(_xlpm.teamNo,INDIRECT("'"&_xlpm.sh&"'!C"&_xlpm.startRow&":C"&(_xlpm.startRow+19)),INDIRECT("'"&_xlpm.sh&"'!F"&_xlpm.startRow&":F"&(_xlpm.startRow+19)),INDIRECT("'"&_xlpm.sh&"'!I"&_xlpm.startRow&":I"&(_xlpm.startRow+19)),INDIRECT("'"&_xlpm.sh&"'!L"&_xlpm.startRow&":L"&(_xlpm.startRow+19))),_xlfn._xlws.FILTER(Summary!D7:W7,TRANSPOSE(IFERROR(--_xlpm.counts,0))<1,"")))}
A8: B | B8: Canada | C8: CAN | D8: {=IF($B8="Other",_xlfn.LET(_xlpm.num,IFERROR(--Others!$B$3,0),IF(_xlpm.num<1,Summary!D8,"")),IF($C8="FWC",_xlfn.LET(_xlpm.codes,_xlfn._xlws.FILTER(Summary!D8:W8,Summary!D8:W8<>""),_xlpm.nums,TRANSPOSE(IFERROR(--Others!$F$3:$F$21,0)),IFERROR(_xlfn.TEXTJOIN(", ",TRUE,_xlfn._xlws.FILTER(_xlpm.codes,_xlpm.nums<1)),"")),IF($C8="CC",_xlfn.LET(_xlpm.codes,_xlfn._xlws.FILTER(Summary!D8:W8,Summary!D8:W8<>""),_xlpm.nums,TRANSPOSE(IFERROR(--Others!$J$3:$J$14,0)),IFERROR(_xlfn.TEXTJOIN(", ",TRUE,_xlfn._xlws.FILTER(_xlpm.codes,_xlpm.nums<1)),"")),IF($C8="","",_xlfn.LET(_xlpm.idx,COUNTIF($C$3:INDEX($C:$C,ROW()),"<>"),_xlpm.grpNo,ROUNDUP(_xlpm.idx/4,0),_xlpm.sh,CHOOSE(ROUNDUP(_xlpm.grpNo/2,0),"A-B","C-D","E-F","G-H","I-J","K-L"),_xlpm.startRow,IF(ISODD(_xlpm.grpNo),5,29),_xlpm.teamNo,MOD(_xlpm.idx-1,4)+1,_xlpm.counts,CHOOSE(_xlpm.teamNo,INDIRECT("'"&_xlpm.sh&"'!C"&_xlpm.startRow&":C"&(_xlpm.startRow+19)),INDIRECT("'"&_xlpm.sh&"'!F"&_xlpm.startRow&":F"&(_xlpm.startRow+19)),INDIRECT("'"&_xlpm.sh&"'!I"&_xlpm.startRow&":I"&(_xlpm.startRow+19)),INDIRECT("'"&_xlpm.sh&"'!L"&_xlpm.startRow&":L"&(_xlpm.startRow+19))),_xlpm.nums,TRANSPOSE(IFERROR(--_xlpm.counts,0)),_xlpm.codes,Summary!D8:W8,IFERROR(_xlfn.TEXTJOIN(", ",TRUE,_xlfn._xlws.FILTER(_xlpm.codes,_xlpm.nums<1)),""))))))} -> CAN 1, CAN 2, CAN 3, CAN 4, CAN 5, CAN 6, CAN 7, CAN 8, CAN 9, CAN 10, CAN 11, CAN 12, CAN 13, CAN 14, CAN 15, CAN 16, CAN 17, CAN 18, CAN 19, CAN 20
A9: B | B9: Bosnia-Herzegovina | C9: BIH | D9: {=IF($B9="Other",_xlfn.LET(_xlpm.num,IFERROR(--Others!$B$3,0),IF(_xlpm.num<1,Summary!D9,"")),IF($C9="FWC",_xlfn.LET(_xlpm.codes,_xlfn._xlws.FILTER(Summary!D9:W9,Summary!D9:W9<>""),_xlpm.nums,TRANSPOSE(IFERROR(--Others!$F$3:$F$21,0)),IFERROR(_xlfn.TEXTJOIN(", ",TRUE,_xlfn._xlws.FILTER(_xlpm.codes,_xlpm.nums<1)),"")),IF($C9="CC",_xlfn.LET(_xlpm.codes,_xlfn._xlws.FILTER(Summary!D9:W9,Summary!D9:W9<>""),_xlpm.nums,TRANSPOSE(IFERROR(--Others!$J$3:$J$14,0)),IFERROR(_xlfn.TEXTJOIN(", ",TRUE,_xlfn._xlws.FILTER(_xlpm.codes,_xlpm.nums<1)),"")),IF($C9="","",_xlfn.LET(_xlpm.idx,COUNTIF($C$3:INDEX($C:$C,ROW()),"<>"),_xlpm.grpNo,ROUNDUP(_xlpm.idx/4,0),_xlpm.sh,CHOOSE(ROUNDUP(_xlpm.grpNo/2,0),"A-B","C-D","E-F","G-H","I-J","K-L"),_xlpm.startRow,IF(ISODD(_xlpm.grpNo),5,29),_xlpm.teamNo,MOD(_xlpm.idx-1,4)+1,_xlpm.counts,CHOOSE(_xlpm.teamNo,INDIRECT("'"&_xlpm.sh&"'!C"&_xlpm.startRow&":C"&(_xlpm.startRow+19)),INDIRECT("'"&_xlpm.sh&"'!F"&_xlpm.startRow&":F"&(_xlpm.startRow+19)),INDIRECT("'"&_xlpm.sh&"'!I"&_xlpm.startRow&":I"&(_xlpm.startRow+19)),INDIRECT("'"&_xlpm.sh&"'!L"&_xlpm.startRow&":L"&(_xlpm.startRow+19))),_xlpm.nums,TRANSPOSE(IFERROR(--_xlpm.counts,0)),_xlpm.codes,Summary!D9:W9,IFERROR(_xlfn.TEXTJOIN(", ",TRUE,_xlfn._xlws.FILTER(_xlpm.codes,_xlpm.nums<1)),""))))))} -> BIH 1, BIH 2, BIH 3, BIH 4, BIH 5, BIH 6, BIH 7, BIH 8, BIH 9, BIH 10, BIH 11, BIH 12, BIH 13, BIH 14, BIH 15, BIH 16, BIH 17, BIH 18, BIH 19, BIH 20
A10: B | B10: Qatar | C10: QAT | D10: {=IF($B10="Other",_xlfn.LET(_xlpm.num,IFERROR(--Others!$B$3,0),IF(_xlpm.num<1,Summary!D10,"")),IF($C10="FWC",_xlfn.LET(_xlpm.codes,_xlfn._xlws.FILTER(Summary!D10:W10,Summary!D10:W10<>""),_xlpm.nums,TRANSPOSE(IFERROR(--Others!$F$3:$F$21,0)),IFERROR(_xlfn.TEXTJOIN(", ",TRUE,_xlfn._xlws.FILTER(_xlpm.codes,_xlpm.nums<1)),"")),IF($C10="CC",_xlfn.LET(_xlpm.codes,_xlfn._xlws.FILTER(Summary!D10:W10,Summary!D10:W10<>""),_xlpm.nums,TRANSPOSE(IFERROR(--Others!$J$3:$J$14,0)),IFERROR(_xlfn.TEXTJOIN(", ",TRUE,_xlfn._xlws.FILTER(_xlpm.codes,_xlpm.nums<1)),"")),IF($C10="","",_xlfn.LET(_xlpm.idx,COUNTIF($C$3:INDEX($C:$C,ROW()),"<>"),_xlpm.grpNo,ROUNDUP(_xlpm.idx/4,0),_xlpm.sh,CHOOSE(ROUNDUP(_xlpm.grpNo/2,0),"A-B","C-D","E-F","G-H","I-J","K-L"),_xlpm.startRow,IF(ISODD(_xlpm.grpNo),5,29),_xlpm.teamNo,MOD(_xlpm.idx-1,4)+1,_xlpm.counts,CHOOSE(_xlpm.teamNo,INDIRECT("'"&_xlpm.sh&"'!C"&_xlpm.startRow&":C"&(_xlpm.startRow+19)),INDIRECT("'"&_xlpm.sh&"'!F"&_xlpm.startRow&":F"&(_xlpm.startRow+19)),INDIRECT("'"&_xlpm.sh&"'!I"&_xlpm.startRow&":I"&(_xlpm.startRow+19)),INDIRECT("'"&_xlpm.sh&"'!L"&_xlpm.startRow&":L"&(_xlpm.startRow+19))),_xlpm.nums,TRANSPOSE(IFERROR(--_xlpm.counts,0)),_xlpm.codes,Summary!D10:W10,IFERROR(_xlfn.TEXTJOIN(", ",TRUE,_xlfn._xlws.FILTER(_xlpm.codes,_xlpm.nums<1)),""))))))} -> QAT 1, QAT 2, QAT 3, QAT 4, QAT 6, QAT 7, QAT 8, QAT 9, QAT 10, QAT 11, QAT 12, QAT 13, QAT 14, QAT 15, QAT 16, QAT 17, QAT 18, QAT 19, QAT 20
A11: B | B11: Switzerland | C11: SUI | D11: {=IF($B11="Other",_xlfn.LET(_xlpm.num,IFERROR(--Others!$B$3,0),IF(_xlpm.num<1,Summary!D11,"")),IF($C11="FWC",_xlfn.LET(_xlpm.codes,_xlfn._xlws.FILTER(Summary!D11:W11,Summary!D11:W11<>""),_xlpm.nums,TRANSPOSE(IFERROR(--Others!$F$3:$F$21,0)),IFERROR(_xlfn.TEXTJOIN(", ",TRUE,_xlfn._xlws.FILTER(_xlpm.codes,_xlpm.nums<1)),"")),IF($C11="CC",_xlfn.LET(_xlpm.codes,_xlfn._xlws.FILTER(Summary!D11:W11,Summary!D11:W11<>""),_xlpm.nums,TRANSPOSE(IFERROR(--Others!$J$3:$J$14,0)),IFERROR(_xlfn.TEXTJOIN(", ",TRUE,_xlfn._xlws.FILTER(_xlpm.codes,_xlpm.nums<1)),"")),IF($C11="","",_xlfn.LET(_xlpm.idx,COUNTIF($C$3:INDEX($C:$C,ROW()),"<>"),_xlpm.grpNo,ROUNDUP(_xlpm.idx/4,0),_xlpm.sh,CHOOSE(ROUNDUP(_xlpm.grpNo/2,0),"A-B","C-D","E-F","G-H","I-J","K-L"),_xlpm.startRow,IF(ISODD(_xlpm.grpNo),5,29),_xlpm.teamNo,MOD(_xlpm.idx-1,4)+1,_xlpm.counts,CHOOSE(_xlpm.teamNo,INDIRECT("'"&_xlpm.sh&"'!C"&_xlpm.startRow&":C"&(_xlpm.startRow+19)),INDIRECT("'"&_xlpm.sh&"'!F"&_xlpm.startRow&":F"&(_xlpm.startRow+19)),INDIRECT("'"&_xlpm.sh&"'!I"&_xlpm.startRow&":I"&(_xlpm.startRow+19)),INDIRECT("'"&_xlpm.sh&"'!L"&_xlpm.startRow&":L"&(_xlpm.startRow+19))),_xlpm.nums,TRANSPOSE(IFERROR(--_xlpm.counts,0)),_xlpm.codes,Summary!D11:W11,IFERROR(_xlfn.TEXTJOIN(", ",TRUE,_xlfn._xlws.FILTER(_xlpm.codes,_xlpm.nums<1)),""))))))} -> SUI 1, SUI 2, SUI 3, SUI 4, SUI 5, SUI 6, SUI 7, SUI 8, SUI 9, SUI 10, SUI 11, SUI 12, SUI 13, SUI 14, SUI 15, SUI 16, SUI 17, SUI 18, SUI 19, SUI 20
D12: {=IF($C12="","",_xlfn.LET(_xlpm.grp,$A12,_xlpm.sh,CHOOSE(ROUNDUP((CODE(_xlpm.grp)-64)/2,0),"A-B","C-D","E-F","G-H","I-J","K-L"),_xlpm.startRow,IF(ISODD(CODE(_xlpm.grp)-64),5,29),_xlpm.teamNo,COUNTIF($A$3:$A12,_xlpm.grp),_xlpm.counts,CHOOSE(_xlpm.teamNo,INDIRECT("'"&_xlpm.sh&"'!C"&_xlpm.startRow&":C"&(_xlpm.startRow+19)),INDIRECT("'"&_xlpm.sh&"'!F"&_xlpm.startRow&":F"&(_xlpm.startRow+19)),INDIRECT("'"&_xlpm.sh&"'!I"&_xlpm.startRow&":I"&(_xlpm.startRow+19)),INDIRECT("'"&_xlpm.sh&"'!L"&_xlpm.startRow&":L"&(_xlpm.startRow+19))),_xlfn._xlws.FILTER(Summary!D12:W12,TRANSPOSE(IFERROR(--_xlpm.counts,0))<1,"")))}
A13: C | B13: Brazil | C13: BRA | D13: {=IF($B13="Other",_xlfn.LET(_xlpm.num,IFERROR(--Others!$B$3,0),IF(_xlpm.num<1,Summary!D13,"")),IF($C13="FWC",_xlfn.LET(_xlpm.codes,_xlfn._xlws.FILTER(Summary!D13:W13,Summary!D13:W13<>""),_xlpm.nums,TRANSPOSE(IFERROR(--Others!$F$3:$F$21,0)),IFERROR(_xlfn.TEXTJOIN(", ",TRUE,_xlfn._xlws.FILTER(_xlpm.codes,_xlpm.nums<1)),"")),IF($C13="CC",_xlfn.LET(_xlpm.codes,_xlfn._xlws.FILTER(Summary!D13:W13,Summary!D13:W13<>""),_xlpm.nums,TRANSPOSE(IFERROR(--Others!$J$3:$J$14,0)),IFERROR(_xlfn.TEXTJOIN(", ",TRUE,_xlfn._xlws.FILTER(_xlpm.codes,_xlpm.nums<1)),"")),IF($C13="","",_xlfn.LET(_xlpm.idx,COUNTIF($C$3:INDEX($C:$C,ROW()),"<>"),_xlpm.grpNo,ROUNDUP(_xlpm.idx/4,0),_xlpm.sh,CHOOSE(ROUNDUP(_xlpm.grpNo/2,0),"A-B","C-D","E-F","G-H","I-J","K-L"),_xlpm.startRow,IF(ISODD(_xlpm.grpNo),5,29),_xlpm.teamNo,MOD(_xlpm.idx-1,4)+1,_xlpm.counts,CHOOSE(_xlpm.teamNo,INDIRECT("'"&_xlpm.sh&"'!C"&_xlpm.startRow&":C"&(_xlpm.startRow+19)),INDIRECT("'"&_xlpm.sh&"'!F"&_xlpm.startRow&":F"&(_xlpm.startRow+19)),INDIRECT("'"&_xlpm.sh&"'!I"&_xlpm.startRow&":I"&(_xlpm.startRow+19)),INDIRECT("'"&_xlpm.sh&"'!L"&_xlpm.startRow&":L"&(_xlpm.startRow+19))),_xlpm.nums,TRANSPOSE(IFERROR(--_xlpm.counts,0)),_xlpm.codes,Summary!D13:W13,IFERROR(_xlfn.TEXTJOIN(", ",TRUE,_xlfn._xlws.FILTER(_xlpm.codes,_xlpm.nums<1)),""))))))} -> BRA 1, BRA 2, BRA 3, BRA 4, BRA 5, BRA 6, BRA 7, BRA 8, BRA 9, BRA 10, BRA 11, BRA 12, BRA 13, BRA 14, BRA 15, BRA 16, BRA 17, BRA 18, BRA 19, BRA 20
A14: C | B14: Morocco | C14: MAR | D14: {=IF($B14="Other",_xlfn.LET(_xlpm.num,IFERROR(--Others!$B$3,0),IF(_xlpm.num<1,Summary!D14,"")),IF($C14="FWC",_xlfn.LET(_xlpm.codes,_xlfn._xlws.FILTER(Summary!D14:W14,Summary!D14:W14<>""),_xlpm.nums,TRANSPOSE(IFERROR(--Others!$F$3:$F$21,0)),IFERROR(_xlfn.TEXTJOIN(", ",TRUE,_xlfn._xlws.FILTER(_xlpm.codes,_xlpm.nums<1)),"")),IF($C14="CC",_xlfn.LET(_xlpm.codes,_xlfn._xlws.FILTER(Summary!D14:W14,Summary!D14:W14<>""),_xlpm.nums,TRANSPOSE(IFERROR(--Others!$J$3:$J$14,0)),IFERROR(_xlfn.TEXTJOIN(", ",TRUE,_xlfn._xlws.FILTER(_xlpm.codes,_xlpm.nums<1)),"")),IF($C14="","",_xlfn.LET(_xlpm.idx,COUNTIF($C$3:INDEX($C:$C,ROW()),"<>"),_xlpm.grpNo,ROUNDUP(_xlpm.idx/4,0),_xlpm.sh,CHOOSE(ROUNDUP(_xlpm.grpNo/2,0),"A-B","C-D","E-F","G-H","I-J","K-L"),_xlpm.startRow,IF(ISODD(_xlpm.grpNo),5,29),_xlpm.teamNo,MOD(_xlpm.idx-1,4)+1,_xlpm.counts,CHOOSE(_xlpm.teamNo,INDIRECT("'"&_xlpm.sh&"'!C"&_xlpm.startRow&":C"&(_xlpm.startRow+19)),INDIRECT("'"&_xlpm.sh&"'!F"&_xlpm.startRow&":F"&(_xlpm.startRow+19)),INDIRECT("'"&_xlpm.sh&"'!I"&_xlpm.startRow&":I"&(_xlpm.startRow+19)),INDIRECT("'"&_xlpm.sh&"'!L"&_xlpm.startRow&":L"&(_xlpm.startRow+19))),_xlpm.nums,TRANSPOSE(IFERROR(--_xlpm.counts,0)),_xlpm.codes,Summary!D14:W14,IFERROR(_xlfn.TEXTJOIN(", ",TRUE,_xlfn._xlws.FILTER(_xlpm.codes,_xlpm.nums<1)),""))))))} -> MAR 1, MAR 2, MAR 3, MAR 4, MAR 5, MAR 6, MAR 7, MAR 8, MAR 9, MAR 10, MAR 11, MAR 12, MAR 13, MAR 14, MAR 15, MAR 16, MAR 17, MAR 18, MAR 19, MAR 20
